Workbook

Sheet metadata
A1: family | B1: vehicles | C1: name | D1: fuel | E1: size | F1: trips_day | G1: survival | H1: survival_param_a | I1: survival_param_b | J1: sppm | K1: Category_EEA | L1: Fuel_EEA | M1: Segment_EEA | N1: Mode_EEA | O1: Slope_EEA | P1: Load_EEA | Q1: speed | R1: driving_cycle | S1: km_cycle | T1: note | U1: v_eea_old | V1: t_eea_old | W1: cc_eea_old | X1: fuel_eea_old
A2: PC | B2: PC_MINI_G | C2: Passenger cars mini with gasoline | D2: G | E2: <1400cc | F2: 4.5 | G2: gompertz | H2: 1.798 | I2: -0.137 | J2: =IF(D2="D", 250, 50) -> 50 | K2: Passenger Cars | L2: =IF(D2="G","Petrol",IF(D2="D","Diesel",IF(D2="HY","Petrol Hybrid",IF(D2="GLP","LPG Bifuell ~ LPG",D2)))) -> Petrol | M2: Small | Q2: 34.2 | R2: FTP-75 | S2: 17.787 | U2: PC | V2: 4S | W2: <=1400 | X2: =D2 -> G
A3: PC | B3: PC_SMALL_G | C3: Passenger cars small with gasoline | D3: G | E3: 1400-2000cc | F3: 4.5 | G3: gompertz | H3: 1.798 | I3: -0.137 | J3: =IF(D3="D", 250, 50) -> 50 | K3: Passenger Cars | L3: =IF(D3="G","Petrol",IF(D3="D","Diesel",IF(D3="HY","Petrol Hybrid",IF(D3="GLP","LPG Bifuell ~ LPG",D3)))) -> Petrol | M3: Small | Q3: 34.2 | R3: FTP-75 | S3: 17.787 | U3: PC | V3: 4S | W3: <=1400 | X3: =D3 -> G
A4: PC | B4: PC_MEDIUM_G | C4: Passenger cars medium with gasoline | D4: G | E4: >2000cc | F4: 4.5 | G4: gompertz | H4: 1.798 | I4: -0.137 | J4: =IF(D4="D", 250, 50) -> 50 | K4: Passenger Cars | L4: =IF(D4="G","Petrol",IF(D4="D","Diesel",IF(D4="HY","Petrol Hybrid",IF(D4="GLP","LPG Bifuell ~ LPG",D4)))) -> Petrol | M4: Medium | Q4: 34.2 | R4: FTP-75 | S4: 17.787 | U4: PC | V4: 4S | W4: 1400_2000 | X4: =D4 -> G
A5: PC | B5: PC_SUV_G | C5: Sport utility vehicle with gasoline | D5: G | E5: >1400cc | F5: 4.5 | G5: gompertz | H5: 1.798 | I5: -0.137 | J5: =IF(D5="D", 250, 50) -> 50 | K5: Passenger Cars | L5: =IF(D5="G","Petrol",IF(D5="D","Diesel",IF(D5="HY","Petrol Hybrid",IF(D5="GLP","LPG Bifuell ~ LPG",D5)))) -> Petrol | M5: Large-SUV-Executive | Q5: 34.2 | R5: FTP-75 | S5: 17.787 | U5: PC | V5: 4S | W5: >2000 | X5: =D5 -> G
A6: PC | B6: PC_MINI_D | C6: Passenger cars mini with gasoline | D6: D | E6: <1400cc | F6: 4.5 | G6: gompertz | H6: 1.798 | I6: -0.137 | J6: =IF(D6="D", 250, 50) -> 250 | K6: Passenger Cars | L6: =IF(D6="G","Petrol",IF(D6="D","Diesel",IF(D6="HY","Petrol Hybrid",IF(D6="GLP","LPG Bifuell ~ LPG",D6)))) -> Diesel | M6: Small | Q6: 34.2 | R6: FTP-75 | S6: 17.787 | U6: PC | V6: 4S | W6: <=1400 | X6: =D6 -> D
A7: PC | B7: PC_SMALL_D | C7: Passenger cars small with gasoline | D7: D | E7: 1400-2000cc | F7: 4.5 | G7: gompertz | H7: 1.798 | I7: -0.137 | J7: =IF(D7="D", 250, 50) -> 250 | K7: Passenger Cars | L7: =IF(D7="G","Petrol",IF(D7="D","Diesel",IF(D7="HY","Petrol Hybrid",IF(D7="GLP","LPG Bifuell ~ LPG",D7)))) -> Diesel | M7: Small | Q7: 34.2 | R7: FTP-75 | S7: 17.787 | U7: PC | V7: 4S | W7: <=1400 | X7: =D7 -> D
A8: PC | B8: PC_MEDIUM_D | C8: Passenger cars medium with gasoline | D8: D | E8: >2000cc | F8: 4.5 | G8: gompertz | H8: 1.798 | I8: -0.137 | J8: =IF(D8="D", 250, 50) -> 250 | K8: Passenger Cars | L8: =IF(D8="G","Petrol",IF(D8="D","Diesel",IF(D8="HY","Petrol Hybrid",IF(D8="GLP","LPG Bifuell ~ LPG",D8)))) -> Diesel | M8: Medium | Q8: 34.2 | R8: FTP-75 | S8: 17.787 | U8: PC | V8: 4S | W8: 1400_2000 | X8: =D8 -> D
A9: PC | B9: PC_SUV_D | C9: Sport utility vehicle with gasoline | D9: D | E9: >1400cc | F9: 4.5 | G9: gompertz | H9: 1.798 | I9: -0.137 | J9: =IF(D9="D", 250, 50) -> 250 | K9: Passenger Cars | L9: =IF(D9="G","Petrol",IF(D9="D","Diesel",IF(D9="HY","Petrol Hybrid",IF(D9="GLP","LPG Bifuell ~ LPG",D9)))) -> Diesel | M9: Large-SUV-Executive | Q9: 34.2 | R9: FTP-75 | S9: 17.787 | U9: PC | V9: 4S | W9: >2000 | X9: =D9 -> D
A10: PC | B10: PC_ELEC | C10: Passenger cars electric | D10: ELEC | E10: all | F10: 4.5 | G10: gompertz | H10: 1.798 | I10: -0.137 | J10: =IF(D10="D", 250, 50) -> 50 | K10: Passenger Cars | L10: =IF(D10="G","Petrol",IF(D10="D","Diesel",IF(D10="HY","Petrol Hybrid",IF(D10="GLP","LPG Bifuell ~ LPG",D10)))) -> ELEC | M10: Small | Q10: 34.2 | R10: FTP-75 | S10: 17.787 | U10: PC | V10: 4S | W10: <=1400 | X10: =D10 -> ELEC
A11: PC | B11: PC_SMALL_HY | C11: Passenger cars small with gasoline | D11: HY | E11: 1400-2000cc | F11: 4.5 | G11: gompertz | H11: 1.798 | I11: -0.137 | J11: =IF(D11="D", 250, 50) -> 50 | K11: Passenger Cars | L11: =IF(D11="G","Petrol",IF(D11="D","Diesel",IF(D11="HY","Petrol Hybrid",IF(D11="GLP","LPG Bifuell ~ LPG",D11)))) -> Petrol Hybrid | M11: Small | Q11: 34.2 | R11: FTP-75 | S11: 17.787 | U11: PC | V11: 4S | W11: 1400_2000 | X11: FH
A12: PC | B12: TAXI_SMALL_G | C12: Taxi small with gasoline | D12: G | E12: 1400-2000cc | F12: 4.5 | G12: gompertz | H12: 1.798 | I12: -0.137 | J12: =IF(D12="D", 250, 50) -> 50 | K12: Passenger Cars | L12: =IF(D12="G","Petrol",IF(D12="D","Diesel",IF(D12="HY","Petrol Hybrid",IF(D12="GLP","LPG Bifuell ~ LPG",D12)))) -> Petrol | M12: Small | Q12: 34.2 | R12: FTP-75 | S12: 17.787 | U12: PC | V12: 4S | W12: 1400_2000 | X12: =D12 -> G
A13: PC | B13: TAXI_SMALL_GLP | C13: Taxi small with glp | D13: GLP | E13: 1400-2000cc | F13: 4.5 | G13: gompertz | H13: 1.798 | I13: -0.137 | J13: =IF(D13="D", 250, 50) -> 50 | K13: Passenger Cars | L13: =IF(D13="G","Petrol",IF(D13="D","Diesel",IF(D13="HY","Petrol Hybrid",IF(D13="GLP","LPG Bifuell ~ LPG",D13)))) -> LPG Bifuell ~ LPG | M13: Small | Q13: 34.2 | R13: FTP-75 | S13: 17.787 | U13: PC | V13: 4S | W13: 1400_2000 | X13: LPG
A14: LCV | B14: LCV_NI_G | C14: Light commercial vehicles N1 with gasoline | D14: G | E14: <=1.305t | F14: 4.5 | G14: gompertz | H14: 1.618 | I14: -0.141 | J14: =IF(D14="D", 250, 50) -> 50 | K14: Light Commercial Vehicles | L14: =IF(D14="G","Petrol",IF(D14="D","Diesel",IF(D14="HY","Petrol Hybrid",IF(D14="GLP","LPG Bifuell ~ LPG",D14)))) -> Petrol | M14: N1-I | Q14: 34.2 | R14: FTP-75 | S14: 17.787 | U14: LCV | V14: 4S | W14: <3.5 | X14: =D14 -> G
A15: LCV | B15: LCV_NII_G | C15: Light commercial vehicles N2 with gasoline | D15: G | E15: 1.305-1.76t | F15: 4.5 | G15: gompertz | H15: 1.618 | I15: -0.141 | J15: =IF(D15="D", 250, 50) -> 50 | K15: Light Commercial Vehicles | L15: =IF(D15="G","Petrol",IF(D15="D","Diesel",IF(D15="HY","Petrol Hybrid",IF(D15="GLP","LPG Bifuell ~ LPG",D15)))) -> Petrol | M15: N1-II | Q15: 34.2 | R15: FTP-75 | S15: 17.787 | U15: LCV | V15: 4S | W15: <3.5 | X15: =D15 -> G
A16: LCV | B16: LCV_NIII_G | C16: Light commercial vehicles N3 with gasoline | D16: G | E16: >=1.76t | F16: 4.5 | G16: gompertz | H16: 1.618 | I16: -0.141 | J16: =IF(D16="D", 250, 50) -> 50 | K16: Light Commercial Vehicles | L16: =IF(D16="G","Petrol",IF(D16="D","Diesel",IF(D16="HY","Petrol Hybrid",IF(D16="GLP","LPG Bifuell ~ LPG",D16)))) -> Petrol | M16: N1-III | Q16: 34.2 | R16: FTP-75 | S16: 17.787 | U16: LCV | V16: 4S | W16: <3.5 | X16: =D16 -> G
A17: LCV | B17: LCV_NI_D | C17: Light commercial vehicles N1 with diesel | D17: D | E17: <=1.305t | F17: 4.5 | G17: double_logistic | H17: 0.1 | I17: 17 | J17: =IF(D17="D", 250, 50) -> 250 | K17: Light Commercial Vehicles | L17: =IF(D17="G","Petrol",IF(D17="D","Diesel",IF(D17="HY","Petrol Hybrid",IF(D17="GLP","LPG Bifuell ~ LPG",D17)))) -> Diesel | M17: N1-I | Q17: 34.2 | R17: FTP-75 | S17: 17.787 | U17: LCV | V17: 4S | W17: <3.5 | X17: =D17 -> D
A18: LCV | B18: LCV_NII_D | C18: Light commercial vehicles N2 with diesel | D18: D | E18: 1.305-1.76t | F18: 4.5 | G18: double_logistic | H18: 0.1 | I18: 17 | J18: =IF(D18="D", 250, 50) -> 250 | K18: Light Commercial Vehicles | L18: =IF(D18="G","Petrol",IF(D18="D","Diesel",IF(D18="HY","Petrol Hybrid",IF(D18="GLP","LPG Bifuell ~ LPG",D18)))) -> Diesel | M18: N1-II | Q18: 34.2 | R18: FTP-75 | S18: 17.787 | U18: LCV | V18: 4S | W18: <3.5 | X18: =D18 -> D
A19: LCV | B19: LCV_NIII_D | C19: Light commercial vehicles N3 with diesel | D19: D | E19: >=1.76t | F19: 4.5 | G19: double_logistic | H19: 0.1 | I19: 17 | J19: =IF(D19="D", 250, 50) -> 250 | K19: Light Commercial Vehicles | L19: =IF(D19="G","Petrol",IF(D19="D","Diesel",IF(D19="HY","Petrol Hybrid",IF(D19="GLP","LPG Bifuell ~ LPG",D19)))) -> Diesel | M19: N1-III | Q19: 34.2 | R19: FTP-75 | S19: 17.787 | U19: LCV | V19: 4S | W19: <3.5 | X19: =D19 -> D
A20: LCV | B20: LCV_ELEC | C20: Light commercial vehicles electric | D20: ELEC | E20: all | F20: 4.5 | G20: gompertz | H20: 1.798 | I20: -0.137 | J20: =IF(D20="D", 250, 50) -> 50 | K20: Light Commercial Vehicles | L20: =IF(D20="G","Petrol",IF(D20="D","Diesel",IF(D20="HY","Petrol Hybrid",IF(D20="GLP","LPG Bifuell ~ LPG",D20)))) -> ELEC | M20: N1-I | Q20: 34.2 | R20: FTP-75 | S20: 17.787 | U20: LCV | V20: 4S | W20: <3.5 | X20: =D20 -> ELEC
A21: LCV | B21: LCV_HY | C21: Light commercial vehicles electric | D21: HY | E21: all | F21: 4.5 | G21: gompertz | H21: 1.798 | I21: -0.137 | J21: =IF(D21="D", 250, 50) -> 50 | K21: Light Commercial Vehicles | L21: =IF(D21="G","Petrol",IF(D21="D","Diesel",IF(D21="HY","Petrol Hybrid",IF(D21="GLP","LPG Bifuell ~ LPG",D21)))) -> Petrol Hybrid | M21: N1-I | Q21: 34.2 | R21: FTP-75 | S21: 17.787 | U21: PC | V21: 4S | W21: 1400_2000 | X21: FH
A22: TRUCKS | B22: TRUCKS_RT_7_D | C22: =CONCATENATE("Rigid trucks diesel ", E22) -> Rigid trucks diesel <=7.5t | D22: D | E22: <=7.5t | G22: double_logistic | H22: 0.1 | I22: 17 | J22: =IF(D22="D", 250, 50) -> 250 | K22: Heavy Duty Trucks | L22: =IF(D22="G","Petrol",IF(D22="D","Diesel",IF(D22="HY","Petrol Hybrid",IF(D22="GLP","LPG Bifuell ~ LPG",D22)))) -> Diesel | M22: Rigid <=7,5 t | O22: 0 | P22: 0.5 | Q22: 22.8 | R22: City Suburban cycle | S22: 10.752 | U22: Trucks | V22: RT | W22: <=7.5 | X22: =D22 -> D
A23: TRUCKS | B23: TRUCKS_RT_7_12_D | C23: =CONCATENATE("Rigid trucks diesel ", E23) -> Rigid trucks diesel 7.5-12t | D23: D | E23: 7.5-12t | G23: double_logistic | H23: 0.1 | I23: 17 | J23: =IF(D23="D", 250, 50) -> 250 | K23: Heavy Duty Trucks | L23: =IF(D23="G","Petrol",IF(D23="D","Diesel",IF(D23="HY","Petrol Hybrid",IF(D23="GLP","LPG Bifuell ~ LPG",D23)))) -> Diesel | M23: Rigid 7,5 - 12 t | O23: 0 | P23: 0.5 | Q23: 22.8 | R23: City Suburban cycle | S23: 10.752 | U23: Trucks | V23: RT | W23: >7.5 & <=12 | X23: =D23 -> D
A24: TRUCKS | B24: TRUCKS_RT_12_14_D | C24: =CONCATENATE("Rigid trucks diesel ", E24) -> Rigid trucks diesel 12-14t | D24: D | E24: 12-14t | G24: double_logistic | H24: 0.1 | I24: 17 | J24: =IF(D24="D", 250, 50) -> 250 | K24: Heavy Duty Trucks | L24: =IF(D24="G","Petrol",IF(D24="D","Diesel",IF(D24="HY","Petrol Hybrid",IF(D24="GLP","LPG Bifuell ~ LPG",D24)))) -> Diesel | M24: Rigid 12 - 14 t | O24: 0 | P24: 0.5 | Q24: 22.8 | R24: City Suburban cycle | S24: 10.752 | U24: Trucks | V24: RT | W24: >12 & <=14 | X24: =D24 -> D
A25: TRUCKS | B25: TRUCKS_RT_14_16_D | C25: =CONCATENATE("Rigid trucks diesel ", E25) -> Rigid trucks diesel 14-16t | D25: D | E25: 14-16t | G25: double_logistic | H25: 0.1 | I25: 17 | J25: =IF(D25="D", 250, 50) -> 250 | K25: Heavy Duty Trucks | L25: =IF(D25="G","Petrol",IF(D25="D","Diesel",IF(D25="HY","Petrol Hybrid",IF(D25="GLP","LPG Bifuell ~ LPG",D25)))) -> Diesel | M25: Rigid 14 - 20 t | O25: 0 | P25: 0.5 | Q25: 22.8 | R25: City Suburban cycle | S25: 10.752 | U25: Trucks | V25: RT | W25: >14 & <=20 | X25: =D25 -> D
A26: TRUCKS | B26: TRUCKS_RT_16_20_D | C26: =CONCATENATE("Rigid trucks diesel ", E26) -> Rigid trucks diesel 16-20t | D26: D | E26: 16-20t | G26: double_logistic | H26: 0.1 | I26: 17 | J26: =IF(D26="D", 250, 50) -> 250 | K26: Heavy Duty Trucks | L26: =IF(D26="G","Petrol",IF(D26="D","Diesel",IF(D26="HY","Petrol Hybrid",IF(D26="GLP","LPG Bifuell ~ LPG",D26)))) -> Diesel | M26: Rigid 14 - 20 t | O26: 0 | P26: 0.5 | Q26: 22.8 | R26: City Suburban cycle | S26: 10.752 | U26: Trucks | V26: RT | W26: >14 & <=20 | X26: =D26 -> D
A27: TRUCKS | B27: TRUCKS_RT_20_26_D | C27: =CONCATENATE("Rigid trucks diesel ", E27) -> Rigid trucks diesel 20-26t | D27: D | E27: 20-26t | G27: double_logistic | H27: 0.1 | I27: 17 | J27: =IF(D27="D", 250, 50) -> 250 | K27: Heavy Duty Trucks | L27: =IF(D27="G","Petrol",IF(D27="D","Diesel",IF(D27="HY","Petrol Hybrid",IF(D27="GLP","LPG Bifuell ~ LPG",D27)))) -> Diesel | M27: Rigid 20 - 26 t | O27: 0 | P27: 0.5 | Q27: 22.8 | R27: City Suburban cycle | S27: 10.752 | U27: Trucks | V27: RT | W27: >20 & <=26 | X27: =D27 -> D
A28: TRUCKS | B28: TRUCKS_RT_26_28_D | C28: =CONCATENATE("Rigid trucks diesel ", E28) -> Rigid trucks diesel 26-28t | D28: D | E28: 26-28t | G28: double_logistic | H28: 0.1 | I28: 17 | J28: =IF(D28="D", 250, 50) -> 250 | K28: Heavy Duty Trucks | L28: =IF(D28="G","Petrol",IF(D28="D","Diesel",IF(D28="HY","Petrol Hybrid",IF(D28="GLP","LPG Bifuell ~ LPG",D28)))) -> Diesel | M28: Rigid 26 - 28 t | O28: 0 | P28: 0.5 | Q28: 22.8 | R28: City Suburban cycle | S28: 10.752 | U28: Trucks | V28: RT | W28: >26 & <=28 | X28: =D28 -> D
A29: TRUCKS | B29: TRUCKS_RT_28_32_D | C29: =CONCATENATE("Rigid trucks diesel ", E29) -> Rigid trucks diesel 38-32t | D29: D | E29: 38-32t | G29: double_logistic | H29: 0.1 | I29: 17 | J29: =IF(D29="D", 250, 50) -> 250 | K29: Heavy Duty Trucks | L29: =IF(D29="G","Petrol",IF(D29="D","Diesel",IF(D29="HY","Petrol Hybrid",IF(D29="GLP","LPG Bifuell ~ LPG",D29)))) -> Diesel | M29: Rigid 28 - 32 t | O29: 0 | P29: 0.5 | Q29: 22.8 | R29: City Suburban cycle | S29: 10.752 | U29: Trucks | V29: RT | W29: >28 & <=32 | X29: =D29 -> D
A30: TRUCKS | B30: TRUCKS_RT_32_D | C30: =CONCATENATE("Rigid trucks diesel ", E30) -> Rigid trucks diesel >=32t | D30: D | E30: >=32t | G30: double_logistic | H30: 0.1 | I30: 17 | J30: =IF(D30="D", 250, 50) -> 250 | K30: Heavy Duty Trucks | L30: =IF(D30="G","Petrol",IF(D30="D","Diesel",IF(D30="HY","Petrol Hybrid",IF(D30="GLP","LPG Bifuell ~ LPG",D30)))) -> Diesel | M30: Rigid >32 t | O30: 0 | P30: 0.5 | Q30: 22.8 | R30: City Suburban cycle | S30: 10.752 | U30: Trucks | V30: RT | W30: >32 | X30: =D30 -> D
A31: TRUCKS | B31: TRUCKS_RT_7_G | C31: =CONCATENATE("Rigid trucks gasoline ", E31) -> Rigid trucks gasoline <=7.5t | D31: G | E31: <=7.5t | G31: double_logistic | H31: 0.1 | I31: 17 | J31: =IF(D31="D", 250, 50) -> 50 | K31: Passenger Cars | L31: =IF(D31="G","Petrol",IF(D31="D","Diesel",IF(D31="HY","Petrol Hybrid",IF(D31="GLP","LPG Bifuell ~ LPG",D31)))) -> Petrol | M31: Large-SUV-Executive | Q31: 22.8 | R31: City Suburban cycle | S31: 10.752 | T31: tratados como PC para incorporar euro. Camiones gasolineros solo tienen pre-euro | U31: PC | V31: 4S | W31: >2000 | X31: =D31 -> G
A32: TRUCKS | B32: TRUCKS_RT_7_12_G | C32: =CONCATENATE("Rigid trucks gasoline ", E32) -> Rigid trucks gasoline 7.5-12t | D32: G | E32: 7.5-12t | G32: double_logistic | H32: 0.1 | I32: 17 | J32: =IF(D32="D", 250, 50) -> 50 | K32: Passenger Cars | L32: =IF(D32="G","Petrol",IF(D32="D","Diesel",IF(D32="HY","Petrol Hybrid",IF(D32="GLP","LPG Bifuell ~ LPG",D32)))) -> Petrol | M32: Large-SUV-Executive | Q32: 22.8 | R32: City Suburban cycle | S32: 10.752 | U32: PC | V32: 4S | W32: >2000 | X32: =D32 -> G
A33: TRUCKS | B33: TRUCKS_RT_12_14_G | C33: =CONCATENATE("Rigid trucks gasoline ", E33) -> Rigid trucks gasoline 12-14t | D33: G | E33: 12-14t | G33: double_logistic | H33: 0.1 | I33: 17 | J33: =IF(D33="D", 250, 50) -> 50 | K33: Passenger Cars | L33: =IF(D33="G","Petrol",IF(D33="D","Diesel",IF(D33="HY","Petrol Hybrid",IF(D33="GLP","LPG Bifuell ~ LPG",D33)))) -> Petrol | M33: Large-SUV-Executive | Q33: 22.8 | R33: City Suburban cycle | S33: 10.752 | U33: PC | V33: 4S | W33: >2000 | X33: =D33 -> G
A34: TRUCKS | B34: TRUCKS_RT_14_16_G | C34: =CONCATENATE("Rigid trucks gasoline ", E34) -> Rigid trucks gasoline 14-16t | D34: G | E34: 14-16t | G34: double_logistic | H34: 0.1 | I34: 17 | J34: =IF(D34="D", 250, 50) -> 50 | K34: Passenger Cars | L34: =IF(D34="G","Petrol",IF(D34="D","Diesel",IF(D34="HY","Petrol Hybrid",IF(D34="GLP","LPG Bifuell ~ LPG",D34)))) -> Petrol | M34: Large-SUV-Executive | Q34: 22.8 | R34: City Suburban cycle | S34: 10.752 | U34: PC | V34: 4S | W34: >2000 | X34: =D34 -> G
A35: TRUCKS | B35: TRUCKS_RT_16_20_G | C35: =CONCATENATE("Rigid trucks gasoline ", E35) -> Rigid trucks gasoline 16-20t | D35: G | E35: 16-20t | G35: double_logistic | H35: 0.1 | I35: 17 | J35: =IF(D35="D", 250, 50) -> 50 | K35: Passenger Cars | L35: =IF(D35="G","Petrol",IF(D35="D","Diesel",IF(D35="HY","Petrol Hybrid",IF(D35="GLP","LPG Bifuell ~ LPG",D35)))) -> Petrol | M35: Large-SUV-Executive | Q35: 22.8 | R35: City Suburban cycle | S35: 10.752 | U35: PC | V35: 4S | W35: >2000 | X35: =D35 -> G
A36: TRUCKS | B36: TRUCKS_RT_20_26_G | C36: =CONCATENATE("Rigid trucks gasoline ", E36) -> Rigid trucks gasoline 20-26t | D36: G | E36: 20-26t | G36: double_logistic | H36: 0.1 | I36: 17 | J36: =IF(D36="D", 250, 50) -> 50 | K36: Passenger Cars | L36: =IF(D36="G","Petrol",IF(D36="D","Diesel",IF(D36="HY","Petrol Hybrid",IF(D36="GLP","LPG Bifuell ~ LPG",D36)))) -> Petrol | M36: Large-SUV-Executive | Q36: 22.8 | R36: City Suburban cycle | S36: 10.752 | U36: PC | V36: 4S | W36: >2000 | X36: =D36 -> G
A37: TRUCKS | B37: TRUCKS_RT_26_28_G | C37: =CONCATENATE("Rigid trucks gasoline ", E37) -> Rigid trucks gasoline 26-28t | D37: G | E37: 26-28t | G37: double_logistic | H37: 0.1 | I37: 17 | J37: =IF(D37="D", 250, 50) -> 50 | K37: Passenger Cars | L37: =IF(D37="G","Petrol",IF(D37="D","Diesel",IF(D37="HY","Petrol Hybrid",IF(D37="GLP","LPG Bifuell ~ LPG",D37)))) -> Petrol | M37: Large-SUV-Executive | Q37: 22.8 | R37: City Suburban cycle | S37: 10.752 | U37: PC | V37: 4S | W37: >2000 | X37: =D37 -> G
A38: TRUCKS | B38: TRUCKS_RT_28_32_G | C38: =CONCATENATE("Rigid trucks gasoline ", E38) -> Rigid trucks gasoline 38-32t | D38: G | E38: 38-32t | G38: double_logistic | H38: 0.1 | I38: 17 | J38: =IF(D38="D", 250, 50) -> 50 | K38: Passenger Cars | L38: =IF(D38="G","Petrol",IF(D38="D","Diesel",IF(D38="HY","Petrol Hybrid",IF(D38="GLP","LPG Bifuell ~ LPG",D38)))) -> Petrol | M38: Large-SUV-Executive | Q38: 22.8 | R38: City Suburban cycle | S38: 10.752 | U38: PC | V38: 4S | W38: >2000 | X38: =D38 -> G
A39: TRUCKS | B39: TRUCKS_RT_32_G | C39: =CONCATENATE("Rigid trucks gasoline ", E39) -> Rigid trucks gasoline >=32t | D39: G | E39: >=32t | G39: double_logistic | H39: 0.1 | I39: 17 | J39: =IF(D39="D", 250, 50) -> 50 | K39: Passenger Cars | L39: =IF(D39="G","Petrol",IF(D39="D","Diesel",IF(D39="HY","Petrol Hybrid",IF(D39="GLP","LPG Bifuell ~ LPG",D39)))) -> Petrol | M39: Large-SUV-Executive | Q39: 22.8 | R39: City Suburban cycle | S39: 10.752 | U39: PC | V39: 4S | W39: >2000 | X39: =D39 -> G
A40: TRUCKS | B40: TRUCKS_AT_16_20_D | C40: =CONCATENATE("Articulated trucks diesel ", E40) -> Articulated trucks diesel 16-20t | D40: D | E40: 16-20t | G40: double_logistic | H40: 0.1 | I40: 17 | J40: =IF(D40="D", 250, 50) -> 250 | K40: Heavy Duty Trucks | L40: =IF(D40="G","Petrol",IF(D40="D","Diesel",IF(D40="HY","Petrol Hybrid",IF(D40="GLP","LPG Bifuell ~ LPG",D40)))) -> Diesel | M40: Articulated 14 - 20 t | O40: 0 | P40: 0.5 | Q40: 22.8 | R40: City Suburban cycle | S40: 10.752 | U40: Trucks | V40: TT | W40: >20 & <=28 | X40: =D40 -> D
...

Sheet fleet_age
A1: Year | B1: =metadata!B2 -> PC_MINI_G | C1: =metadata!B3 -> PC_SMALL_G | D1: =metadata!B4 -> PC_MEDIUM_G | E1: =metadata!B5 -> PC_SUV_G | F1: =metadata!B6 -> PC_MINI_D | G1: =metadata!B7 -> PC_SMALL_D | H1: =metadata!B8 -> PC_MEDIUM_D | I1: =metadata!B9 -> PC_SUV_D | J1: =metadata!B10 -> PC_ELEC | K1: =metadata!B11 -> PC_SMALL_HY | L1: =metadata!B12 -> TAXI_SMALL_G | M1: =metadata!B13 -> TAXI_SMALL_GLP | N1: =metadata!B14 -> LCV_NI_G | O1: =metadata!B15 -> LCV_NII_G | P1: =metadata!B16 -> LCV_NIII_G | Q1: =metadata!B17 -> LCV_NI_D | R1: =metadata!B18 -> LCV_NII_D | S1: =metadata!B19 -> LCV_NIII_D | T1: =metadata!B20 -> LCV_ELEC | U1: =metadata!B21 -> LCV_HY | V1: =metadata!B22 -> TRUCKS_RT_7_D | W1: =metadata!B23 -> TRUCKS_RT_7_12_D | X1: =metadata!B24 -> TRUCKS_RT_12_14_D | Y1: =metadata!B25 -> TRUCKS_RT_14_16_D | Z1: =metadata!B26 -> TRUCKS_RT_16_20_D | AA1: =metadata!B27 -> TRUCKS_RT_20_26_D | AB1: =metadata!B28 -> TRUCKS_RT_26_28_D | AC1: =metadata!B29 -> TRUCKS_RT_28_32_D | AD1: =metadata!B30 -> TRUCKS_RT_32_D | AE1: =metadata!B31 -> TRUCKS_RT_7_G | AF1: =metadata!B32 -> TRUCKS_RT_7_12_G | AG1: =metadata!B33 -> TRUCKS_RT_12_14_G | AH1: =metadata!B34 -> TRUCKS_RT_14_16_G | AI1: =metadata!B35 -> TRUCKS_RT_16_20_G | AJ1: =metadata!B36 -> TRUCKS_RT_20_26_G | AK1: =metadata!B37 -> TRUCKS_RT_26_28_G | AL1: =metadata!B38 -> TRUCKS_RT_28_32_G | AM1: =metadata!B39 -> TRUCKS_RT_32_G | AN1: =metadata!B40 -> TRUCKS_AT_16_20_D | AO1: =metadata!B41 -> TRUCKS_AT_20_28_D | AP1: =metadata!B42 -> TRUCKS_AT_28_34_D | AQ1: =metadata!B43 -> TRUCKS_AT_34_40_D | AR1: =metadata!B44 -> TRUCKS_AT_40_50_D | AS1: =metadata!B45 -> TRUCKS_AT_50_60_D | AT1: =metadata!B46 -> TRUCKS_ELEC | AU1: =metadata!B47 -> BUS_UB_15_D | AV1: =metadata!B48 -> BUS_UB_15_18_D | AW1: =metadata!B49 -> BUS_UB_18_D | AX1: =metadata!B50 -> BUS_UB_15_G | AY1: =metadata!B51 -> BUS_UB_15_18_G | AZ1: =metadata!B52 -> BUS_UB_18_G | BA1: =metadata!B53 -> BUS_COACH_17_D | BB1: =metadata!B54 -> BUS_COACH_18_D | BC1: =metadata!B55 -> BUS_COACH_17_G | BD1: =metadata!B56 -> BUS_COACH_18_G | BE1: =metadata!B57 -> BUS_UB_15_HY | BF1: =metadata!B58 -> BUS_ELEC | BG1: =metadata!B59 -> MC_2S_50_G | BH1: =metadata!B60 -> MC_4S_50_250_G | BI1: =metadata!B61 -> MC_4S_250_750_G | BJ1: =metadata!B62 -> MC_4S_750_G | BK1: =metadata!B63 -> MC_ELEC
A2: 2017 | B2: =base_fleet!H4 -> 5522 | C2: =base_fleet!M4*0.95 -> 15650.3 | D2: =base_fleet!D4 -> 106 | E2: =base_fleet!R4 -> 24392 | F2: =base_fleet!F4 -> 1 | G2: =base_fleet!K4 -> 10 | H2: =base_fleet!B4 -> 0 | I2: =base_fleet!P4 -> 525 | J2: =base_fleet!C4+base_fleet!G4+base_fleet!L4+base_fleet!Q4 -> 87 | K2: =base_fleet!E4+base_fleet!J4+base_fleet!O4+base_fleet!T4 -> 1571 | L2: =base_fleet!M4*0.05 -> 823.7 | M2: =base_fleet!I4+base_fleet!N4+base_fleet!S4 -> 0 | N2: =base_fleet!AF4 -> 4790 | O2: =base_fleet!AA4 -> 488 | P2: =base_fleet!V4 -> 435 | Q2: =base_fleet!AD4 -> 8926 | R2: =base_fleet!Y4 -> 552 | S2: =base_fleet!U4 -> 493 | T2: =base_fleet!Z4+base_fleet!AE4 -> 0 | U2: =base_fleet!X4+base_fleet!AC4+base_fleet!AH4 -> 2 | V2: =base_fleet!AI4 -> 2936 | W2: =base_fleet!AM4 -> 342 | X2: =base_fleet!AP4 -> 222 | Y2: =base_fleet!AS4 -> 73 | Z2: =base_fleet!AU4 -> 203 | AA2: =base_fleet!AW4 -> 15 | AB2: =base_fleet!AY4/2 -> 16 | AC2: =base_fleet!AY4/2 -> 16 | AD2: =base_fleet!BB4 -> 4 | AE2: =base_fleet!AK4 -> 9 | AF2: =base_fleet!AO4 -> 0 | AG2: =base_fleet!AR4 -> 0 | AH2: =base_fleet!AT4 -> 0 | AI2: =base_fleet!AV4 -> 0 | AJ2: =base_fleet!AX4 -> 0 | AK2: =base_fleet!AZ4 -> 0 | AL2: =base_fleet!BC4 -> 0 | AM2: 0 | AN2: =base_fleet!BD4 -> 164 | AO2: =base_fleet!BE4 -> 90 | AP2: =base_fleet!BF4 -> 1 | AQ2: =base_fleet!BG4 -> 22 | AR2: =base_fleet!BH4 -> 71 | AS2: =base_fleet!BI4 -> 7 | AT2: =base_fleet!AQ4+base_fleet!AN4+base_fleet!AJ4 -> 0 | AU2: =base_fleet!BL4 -> 1210.4 | AV2: =base_fleet!BJ4 -> 302.6 | AW2: =base_fleet!BN4 -> 66.3 | AX2: =base_fleet!BM4 -> 3.4 | AY2: =base_fleet!BK4 -> 0 | AZ2: =base_fleet!BO4 -> 0 | BA2: =base_fleet!BP4 -> 224.1 | BB2: =base_fleet!BR4 -> 0.15 | BC2: =base_fleet!BQ4 -> 1.8 | BD2: =base_fleet!BS4 -> 0 | BE2: 0 | BF2: 0 | BG2: =base_fleet!CE4 -> 3 | BH2: =base_fleet!CA4 -> 73869 | BI2: =base_fleet!BV4 -> 1485 | BJ2: =base_fleet!CH4 -> 2 | BK2: =base_fleet!BU4+base_fleet!BZ4+base_fleet!CD4 -> 76
A3: =A2-1 -> 2016 | B3: =base_fleet!H5 -> 4030 | C3: =base_fleet!M5*0.95 -> 13349.4 | D3: =base_fleet!D5 -> 201 | E3: =base_fleet!R5 -> 14707 | F3: =base_fleet!F5 -> 1 | G3: =base_fleet!K5 -> 193 | H3: =base_fleet!B5 -> 1 | I3: =base_fleet!P5 -> 460 | J3: =base_fleet!C5+base_fleet!G5+base_fleet!L5+base_fleet!Q5 -> 43 | K3: =base_fleet!E5+base_fleet!J5+base_fleet!O5+base_fleet!T5 -> 553 | L3: =base_fleet!M5*0.05 -> 702.6 | M3: =base_fleet!I5+base_fleet!N5+base_fleet!S5 -> 1 | N3: =base_fleet!AF5 -> 2649 | O3: =base_fleet!AA5 -> 390 | P3: =base_fleet!V5 -> 365 | Q3: =base_fleet!AD5 -> 5916 | R3: =base_fleet!Y5 -> 353 | S3: =base_fleet!U5 -> 801 | T3: =base_fleet!Z5+base_fleet!AE5 -> 0 | U3: =base_fleet!X5+base_fleet!AC5+base_fleet!AH5 -> 0 | V3: =base_fleet!AI5 -> 1045 | W3: =base_fleet!AM5 -> 159 | X3: =base_fleet!AP5 -> 18 | Y3: =base_fleet!AS5 -> 45 | Z3: =base_fleet!AU5 -> 43 | AA3: =base_fleet!AW5 -> 10 | AB3: =base_fleet!AY5/2 -> 4 | AC3: =base_fleet!AY5/2 -> 4 | AD3: =base_fleet!BB5 -> 1 | AE3: =base_fleet!AK5 -> 13 | AF3: =base_fleet!AO5 -> 1 | AG3: =base_fleet!AR5 -> 0 | AH3: =base_fleet!AT5 -> 0 | AI3: =base_fleet!AV5 -> 0 | AJ3: =base_fleet!AX5 -> 0 | AK3: =base_fleet!AZ5 -> 0 | AL3: =base_fleet!BC5 -> 0 | AM3: 0 | AN3: =base_fleet!BD5 -> 21 | AO3: =base_fleet!BE5 -> 1 | AP3: =base_fleet!BF5 -> 0 | AQ3: =base_fleet!BG5 -> 0 | AR3: =base_fleet!BH5 -> 1 | AS3: =base_fleet!BI5 -> 0 | AT3: =base_fleet!AQ5+base_fleet!AN5+base_fleet!AJ5 -> 0 | AU3: =base_fleet!BL5 -> 939.25 | AV3: =base_fleet!BJ5 -> 75.65 | AW3: =base_fleet!BN5 -> 17 | AX3: =base_fleet!BM5 -> 1.7 | AY3: =base_fleet!BK5 -> 0 | AZ3: =base_fleet!BO5 -> 0 | BA3: =base_fleet!BP5 -> 162.15 | BB3: =base_fleet!BR5 -> 1.35 | BC3: =base_fleet!BQ5 -> 1.35 | BD3: =base_fleet!BS5 -> 0 | BE3: 0 | BF3: 0 | BG3: =base_fleet!CE5 -> 0 | BH3: =base_fleet!CA5 -> 37270 | BI3: =base_fleet!BV5 -> 465 | BJ3: =base_fleet!CH5 -> 0 | BK3: =base_fleet!BU5+base_fleet!BZ5+base_fleet!CD5 -> 6
A4: =A3-1 -> 2015 | B4: =base_fleet!H6 -> 9792 | C4: =base_fleet!M6*0.95 -> 23799.4 | D4: =base_fleet!D6 -> 36 | E4: =base_fleet!R6 -> 12476 | F4: =base_fleet!F6 -> 1 | G4: =base_fleet!K6 -> 15 | H4: =base_fleet!B6 -> 2 | I4: =base_fleet!P6 -> 123 | J4: =base_fleet!C6+base_fleet!G6+base_fleet!L6+base_fleet!Q6 -> 68 | K4: =base_fleet!E6+base_fleet!J6+base_fleet!O6+base_fleet!T6 -> 717 | L4: =base_fleet!M6*0.05 -> 1252.6 | M4: =base_fleet!I6+base_fleet!N6+base_fleet!S6 -> 1 | N4: =base_fleet!AF6 -> 3757 | O4: =base_fleet!AA6 -> 293 | P4: =base_fleet!V6 -> 1085 | Q4: =base_fleet!AD6 -> 4351 | R4: =base_fleet!Y6 -> 192 | S4: =base_fleet!U6 -> 961 | T4: =base_fleet!Z6+base_fleet!AE6 -> 3 | U4: =base_fleet!X6+base_fleet!AC6+base_fleet!AH6 -> 1 | V4: =base_fleet!AI6 -> 3185 | W4: =base_fleet!AM6 -> 328 | X4: =base_fleet!AP6 -> 81 | Y4: =base_fleet!AS6 -> 200 | Z4: =base_fleet!AU6 -> 165 | AA4: =base_fleet!AW6 -> 18 | AB4: =base_fleet!AY6/2 -> 9.5 | AC4: =base_fleet!AY6/2 -> 9.5 | AD4: =base_fleet!BB6 -> 2 | AE4: =base_fleet!AK6 -> 45 | AF4: =base_fleet!AO6 -> 3 | AG4: =base_fleet!AR6 -> 0 | AH4: =base_fleet!AT6 -> 0 | AI4: =base_fleet!AV6 -> 2 | AJ4: =base_fleet!AX6 -> 0 | AK4: =base_fleet!AZ6 -> 1 | AL4: =base_fleet!BC6 -> 0 | AM4: 0 | AN4: =base_fleet!BD6 -> 118 | AO4: =base_fleet!BE6 -> 112 | AP4: =base_fleet!BF6 -> 3 | AQ4: =base_fleet!BG6 -> 14 | AR4: =base_fleet!BH6 -> 46 | AS4: =base_fleet!BI6 -> 11 | AT4: =base_fleet!AQ6+base_fleet!AN6+base_fleet!AJ6 -> 1 | AU4: =base_fleet!BL6 -> 1212.95 | AV4: =base_fleet!BJ6 -> 135.15 | AW4: =base_fleet!BN6 -> 61.2 | AX4: =base_fleet!BM6 -> 9.35 | AY4: =base_fleet!BK6 -> 0.85 | AZ4: =base_fleet!BO6 -> 0 | BA4: =base_fleet!BP6 -> 169.65 | BB4: =base_fleet!BR6 -> 0.3 | BC4: =base_fleet!BQ6 -> 1.35 | BD4: =base_fleet!BS6 -> 0 | BE4: 0 | BF4: 0 | BG4: =base_fleet!CE6 -> 6 | BH4: =base_fleet!CA6 -> 24810 | BI4: =base_fleet!BV6 -> 86 | BJ4: =base_fleet!CH6 -> 2 | BK4: =base_fleet!BU6+base_fleet!BZ6+base_fleet!CD6 -> 1
A5: =A4-1 -> 2014 | B5: =base_fleet!H7 -> 15449 | C5: =base_fleet!M7*0.95 -> 17061.05 | D5: =base_fleet!D7 -> 78 | E5: =base_fleet!R7 -> 24529 | F5: =base_fleet!F7 -> 1 | G5: =base_fleet!K7 -> 25 | H5: =base_fleet!B7 -> 2 | I5: =base_fleet!P7 -> 93 | J5: =base_fleet!C7+base_fleet!G7+base_fleet!L7+base_fleet!Q7 -> 2 | K5: =base_fleet!E7+base_fleet!J7+base_fleet!O7+base_fleet!T7 -> 85 | L5: =base_fleet!M7*0.05 -> 897.95 | M5: =base_fleet!I7+base_fleet!N7+base_fleet!S7 -> 3 | N5: =base_fleet!AF7 -> 7747 | O5: =base_fleet!AA7 -> 886 | P5: =base_fleet!V7 -> 1496 | Q5: =base_fleet!AD7 -> 8830 | R5: =base_fleet!Y7 -> 648 | S5: =base_fleet!U7 -> 1991 | T5: =base_fleet!Z7+base_fleet!AE7 -> 0 | U5: =base_fleet!X7+base_fleet!AC7+base_fleet!AH7 -> 1 | V5: =base_fleet!AI7 -> 6124 | W5: =base_fleet!AM7 -> 1072 | X5: =base_fleet!AP7 -> 197 | Y5: =base_fleet!AS7 -> 591 | Z5: =base_fleet!AU7 -> 495 | AA5: =base_fleet!AW7 -> 162 | AB5: =base_fleet!AY7/2 -> 103.5 | AC5: =base_fleet!AY7/2 -> 103.5 | AD5: =base_fleet!BB7 -> 8 | AE5: =base_fleet!AK7 -> 60 | AF5: =base_fleet!AO7 -> 5 | AG5: =base_fleet!AR7 -> 2 | AH5: =base_fleet!AT7 -> 2 | AI5: =base_fleet!AV7 -> 5 | AJ5: =base_fleet!AX7 -> 0 | AK5: =base_fleet!AZ7 -> 4 | AL5: =base_fleet!BC7 -> 0 | AM5: 0 | AN5: =base_fleet!BD7 -> 224 | AO5: =base_fleet!BE7 -> 661 | AP5: =base_fleet!BF7 -> 7 | AQ5: =base_fleet!BG7 -> 174 | AR5: =base_fleet!BH7 -> 307 | AS5: =base_fleet!BI7 -> 5 | AT5: =base_fleet!AQ7+base_fleet!AN7+base_fleet!AJ7 -> 0 | AU5: =base_fleet!BL7 -> 1134.75 | AV5: =base_fleet!BJ7 -> 112.2 | AW5: =base_fleet!BN7 -> 68 | AX5: =base_fleet!BM7 -> 10.2 | AY5: =base_fleet!BK7 -> 0 | AZ5: =base_fleet!BO7 -> 0 | BA5: =base_fleet!BP7 -> 198.6 | BB5: =base_fleet!BR7 -> 2.85 | BC5: =base_fleet!BQ7 -> 1.65 | BD5: =base_fleet!BS7 -> 0 | BE5: 0 | BF5: 0 | BG5: =base_fleet!CE7 -> 67 | BH5: =base_fleet!CA7 -> 53787 | BI5: =base_fleet!BV7 -> 127 | BJ5: =base_fleet!CH7 -> 4 | BK5: =base_fleet!BU7+base_fleet!BZ7+base_fleet!CD7 -> 0
A6: =A5-1 -> 2013 | B6: =base_fleet!H8 -> 20796 | C6: =base_fleet!M8*0.95 -> 19845.5 | D6: =base_fleet!D8 -> 64 | E6: =base_fleet!R8 -> 21361 | F6: =base_fleet!F8 -> 3 | G6: =base_fleet!K8 -> 30 | H6: =base_fleet!B8 -> 2 | I6: =base_fleet!P8 -> 74 | J6: =base_fleet!C8+base_fleet!G8+base_fleet!L8+base_fleet!Q8 -> 1 | K6: =base_fleet!E8+base_fleet!J8+base_fleet!O8+base_fleet!T8 -> 342 | L6: =base_fleet!M8*0.05 -> 1044.5 | M6: =base_fleet!I8+base_fleet!N8+base_fleet!S8 -> 2 | N6: =base_fleet!AF8 -> 7038 | O6: =base_fleet!AA8 -> 731 | P6: =base_fleet!V8 -> 1226 | Q6: =base_fleet!AD8 -> 7922 | R6: =base_fleet!Y8 -> 745 | S6: =base_fleet!U8 -> 1266 | T6: =base_fleet!Z8+base_fleet!AE8 -> 0 | U6: =base_fleet!X8+base_fleet!AC8+base_fleet!AH8 -> 1 | V6: =base_fleet!AI8 -> 4776 | W6: =base_fleet!AM8 -> 588 | X6: =base_fleet!AP8 -> 259 | Y6: =base_fleet!AS8 -> 128 | Z6: =base_fleet!AU8 -> 501 | AA6: =base_fleet!AW8 -> 131 | AB6: =base_fleet!AY8/2 -> 68 | AC6: =base_fleet!AY8/2 -> 68 | AD6: =base_fleet!BB8 -> 17 | AE6: =base_fleet!AK8 -> 17 | AF6: =base_fleet!AO8 -> 3 | AG6: =base_fleet!AR8 -> 0 | AH6: =base_fleet!AT8 -> 0 | AI6: =base_fleet!AV8 -> 2 | AJ6: =base_fleet!AX8 -> 2 | AK6: =base_fleet!AZ8 -> 0 | AL6: =base_fleet!BC8 -> 1 | AM6: 0 | AN6: =base_fleet!BD8 -> 217 | AO6: =base_fleet!BE8 -> 552 | AP6: =base_fleet!BF8 -> 16 | AQ6: =base_fleet!BG8 -> 174 | AR6: =base_fleet!BH8 -> 183 | AS6: =base_fleet!BI8 -> 8 | AT6: =base_fleet!AQ8+base_fleet!AN8+base_fleet!AJ8 -> 0 | AU6: =base_fleet!BL8 -> 1153.45 | AV6: =base_fleet!BJ8 -> 281.35 | AW6: =base_fleet!BN8 -> 24.65 | AX6: =base_fleet!BM8 -> 1.7 | AY6: =base_fleet!BK8 -> 0 | AZ6: =base_fleet!BO8 -> 0 | BA6: =base_fleet!BP8 -> 114.15 | BB6: =base_fleet!BR8 -> 0.45 | BC6: =base_fleet!BQ8 -> 1.05 | BD6: =base_fleet!BS8 -> 0 | BE6: 0 | BF6: 0 | BG6: =base_fleet!CE8 -> 35 | BH6: =base_fleet!CA8 -> 46591 | BI6: =base_fleet!BV8 -> 365 | BJ6: =base_fleet!CH8 -> 10 | BK6: =base_fleet!BU8+base_fleet!BZ8+base_fleet!CD8 -> 5
A7: =A6-1 -> 2012 | B7: =base_fleet!H9 -> 17643 | C7: =base_fleet!M9*0.95 -> 25065.75 | D7: =base_fleet!D9 -> 64 | E7: =base_fleet!R9 -> 23514 | F7: =base_fleet!F9 -> 6 | G7: =base_fleet!K9 -> 35 | H7: =base_fleet!B9 -> 1 | I7: =base_fleet!P9 -> 124 | J7: =base_fleet!C9+base_fleet!G9+base_fleet!L9+base_fleet!Q9 -> 1 | K7: =base_fleet!E9+base_fleet!J9+base_fleet!O9+base_fleet!T9 -> 272 | L7: =base_fleet!M9*0.05 -> 1319.25 | M7: =base_fleet!I9+base_fleet!N9+base_fleet!S9 -> 2 | N7: =base_fleet!AF9 -> 12369 | O7: =base_fleet!AA9 -> 1400 | P7: =base_fleet!V9 -> 569 | Q7: =base_fleet!AD9 -> 9792 | R7: =base_fleet!Y9 -> 908 | S7: =base_fleet!U9 -> 456 | T7: =base_fleet!Z9+base_fleet!AE9 -> 3 | U7: =base_fleet!X9+base_fleet!AC9+base_fleet!AH9 -> 0 | V7: =base_fleet!AI9 -> 5860 | W7: =base_fleet!AM9 -> 532 | X7: =base_fleet!AP9 -> 335 | Y7: =base_fleet!AS9 -> 126 | Z7: =base_fleet!AU9 -> 412 | AA7: =base_fleet!AW9 -> 343 | AB7: =base_fleet!AY9/2 -> 56 | AC7: =base_fleet!AY9/2 -> 56 | AD7: =base_fleet!BB9 -> 69 | AE7: =base_fleet!AK9 -> 50 | AF7: =base_fleet!AO9 -> 6 | AG7: =base_fleet!AR9 -> 1 | AH7: =base_fleet!AT9 -> 1 | AI7: =base_fleet!AV9 -> 1 | AJ7: =base_fleet!AX9 -> 6 | AK7: =base_fleet!AZ9 -> 0 | AL7: =base_fleet!BC9 -> 0 | AM7: 0 | AN7: =base_fleet!BD9 -> 219 | AO7: =base_fleet!BE9 -> 523 | AP7: =base_fleet!BF9 -> 15 | AQ7: =base_fleet!BG9 -> 163 | AR7: =base_fleet!BH9 -> 213 | AS7: =base_fleet!BI9 -> 0 | AT7: =base_fleet!AQ9+base_fleet!AN9+base_fleet!AJ9 -> 1 | AU7: =base_fleet!BL9 -> 848.3 | AV7: =base_fleet!BJ9 -> 272 | AW7: =base_fleet!BN9 -> 10.2 | AX7: =base_fleet!BM9 -> 2.55 | AY7: =base_fleet!BK9 -> 0 | AZ7: =base_fleet!BO9 -> 0 | BA7: =base_fleet!BP9 -> 230.7 | BB7: =base_fleet!BR9 -> 2.7 | BC7: =base_fleet!BQ9 -> 2.1 | BD7: =base_fleet!BS9 -> 0 | BE7: 0 | BF7: 0 | BG7: =base_fleet!CE9 -> 11 | BH7: =base_fleet!CA9 -> 34545 | BI7: =base_fleet!BV9 -> 398 | BJ7: =base_fleet!CH9 -> 31 | BK7: =base_fleet!BU9+base_fleet!BZ9+base_fleet!CD9 -> 4
A8: =A7-1 -> 2011 | B8: =base_fleet!H10 -> 16182 | C8: =base_fleet!M10*0.95 -> 32241.1 | D8: =base_fleet!D10 -> 172 | E8: =base_fleet!R10 -> 22476 | F8: =base_fleet!F10 -> 18 | G8: =base_fleet!K10 -> 100 | H8: =base_fleet!B10 -> 1 | I8: =base_fleet!P10 -> 81 | J8: =base_fleet!C10+base_fleet!G10+base_fleet!L10+base_fleet!Q10 -> 2 | K8: =base_fleet!E10+base_fleet!J10+base_fleet!O10+base_fleet!T10 -> 241 | L8: =base_fleet!M10*0.05 -> 1696.9 | M8: =base_fleet!I10+base_fleet!N10+base_fleet!S10 -> 7 | N8: =base_fleet!AF10 -> 11933 | O8: =base_fleet!AA10 -> 2066 | P8: =base_fleet!V10 -> 246 | Q8: =base_fleet!AD10 -> 7033 | R8: =base_fleet!Y10 -> 696 | S8: =base_fleet!U10 -> 586 | T8: =base_fleet!Z10+base_fleet!AE10 -> 0 | U8: =base_fleet!X10+base_fleet!AC10+base_fleet!AH10 -> 1 | V8: =base_fleet!AI10 -> 4794 | W8: =base_fleet!AM10 -> 688 | X8: =base_fleet!AP10 -> 607 | Y8: =base_fleet!AS10 -> 81 | Z8: =base_fleet!AU10 -> 304 | AA8: =base_fleet!AW10 -> 311 | AB8: =base_fleet!AY10/2 -> 4.5 | AC8: =base_fleet!AY10/2 -> 4.5 | AD8: =base_fleet!BB10 -> 36 | AE8: =base_fleet!AK10 -> 50 | AF8: =base_fleet!AO10 -> 4 | AG8: =base_fleet!AR10 -> 4 | AH8: =base_fleet!AT10 -> 0 | AI8: =base_fleet!AV10 -> 1 | AJ8: =base_fleet!AX10 -> 4 | AK8: =base_fleet!AZ10 -> 0 | AL8: =base_fleet!BC10 -> 0 | AM8: 0 | AN8: =base_fleet!BD10 -> 243 | AO8: =base_fleet!BE10 -> 338 | AP8: =base_fleet!BF10 -> 28 | AQ8: =base_fleet!BG10 -> 159 | AR8: =base_fleet!BH10 -> 180 | AS8: =base_fleet!BI10 -> 2 | AT8: =base_fleet!AQ10+base_fleet!AN10+base_fleet!AJ10 -> 0 | AU8: =base_fleet!BL10 -> 935 | AV8: =base_fleet!BJ10 -> 165.75 | AW8: =base_fleet!BN10 -> 4.25 | AX8: =base_fleet!BM10 -> 4.25 | AY8: =base_fleet!BK10 -> 2.55 | AZ8: =base_fleet!BO10 -> 0 | BA8: =base_fleet!BP10 -> 194.25 | BB8: =base_fleet!BR10 -> 0.75 | BC8: =base_fleet!BQ10 -> 1.2 | BD8: =base_fleet!BS10 -> 0 | BE8: 0 | BF8: 0 | BG8: =base_fleet!CE10 -> 4 | BH8: =base_fleet!CA10 -> 36287 | BI8: =base_fleet!BV10 -> 318 | BJ8: =base_fleet!CH10 -> 1 | BK8: =base_fleet!BU10+base_fleet!BZ10+base_fleet!CD10 -> 1
A9: =A8-1 -> 2010 | B9: =base_fleet!H11 -> 11486 | C9: =base_fleet!M11*0.95 -> 16687.7 | D9: =base_fleet!D11 -> 11 | E9: =base_fleet!R11 -> 25762 | F9: =base_fleet!F11 -> 15 | G9: =base_fleet!K11 -> 116 | H9: =base_fleet!B11 -> 3 | I9: =base_fleet!P11 -> 135 | J9: =base_fleet!C11+base_fleet!G11+base_fleet!L11+base_fleet!Q11 -> 2 | K9: =base_fleet!E11+base_fleet!J11+base_fleet!O11+base_fleet!T11 -> 1154 | L9: =base_fleet!M11*0.05 -> 878.3 | M9: =base_fleet!I11+base_fleet!N11+base_fleet!S11 -> 4 | N9: =base_fleet!AF11 -> 13738 | O9: =base_fleet!AA11 -> 1114 | P9: =base_fleet!V11 -> 184 | Q9: =base_fleet!AD11 -> 9413 | R9: =base_fleet!Y11 -> 914 | S9: =base_fleet!U11 -> 758 | T9: =base_fleet!Z11+base_fleet!AE11 -> 0 | U9: =base_fleet!X11+base_fleet!AC11+base_fleet!AH11 -> 73 | V9: =base_fleet!AI11 -> 4665 | W9: =base_fleet!AM11 -> 962 | X9: =base_fleet!AP11 -> 450 | Y9: =base_fleet!AS11 -> 125 | Z9: =base_fleet!AU11 -> 243 | AA9: =base_fleet!AW11 -> 80 | AB9: =base_fleet!AY11/2 -> 17 | AC9: =base_fleet!AY11/2 -> 17 | AD9: =base_fleet!BB11 -> 12 | AE9: =base_fleet!AK11 -> 72 | AF9: =base_fleet!AO11 -> 5 | AG9: =base_fleet!AR11 -> 2 | AH9: =base_fleet!AT11 -> 3 | AI9: =base_fleet!AV11 -> 1 | AJ9: =base_fleet!AX11 -> 1 | AK9: =base_fleet!AZ11 -> 0 | AL9: =base_fleet!BC11 -> 0 | AM9: 0 | AN9: =base_fleet!BD11 -> 217 | AO9: =base_fleet!BE11 -> 343 | AP9: =base_fleet!BF11 -> 34 | AQ9: =base_fleet!BG11 -> 96 | AR9: =base_fleet!BH11 -> 75 | AS9: =base_fleet!BI11 -> 0 | AT9: =base_fleet!AQ11+base_fleet!AN11+base_fleet!AJ11 -> 0 | AU9: =base_fleet!BL11 -> 1021.7 | AV9: =base_fleet!BJ11 -> 285.6 | AW9: =base_fleet!BN11 -> 15.3 | AX9: =base_fleet!BM11 -> 10.2 | AY9: =base_fleet!BK11 -> 1.7 | AZ9: =base_fleet!BO11 -> 0 | BA9: =base_fleet!BP11 -> 197.7 | BB9: =base_fleet!BR11 -> 1.8 | BC9: =base_fleet!BQ11 -> 0.45 | BD9: =base_fleet!BS11 -> 0 | BE9: 0 | BF9: 0 | BG9: =base_fleet!CE11 -> 5 | BH9: =base_fleet!CA11 -> 22764 | BI9: =base_fleet!BV11 -> 50 | BJ9: =base_fleet!CH11 -> 3 | BK9: =base_fleet!BU11+base_fleet!BZ11+base_fleet!CD11 -> 1
A10: =A9-1 -> 2009 | B10: =base_fleet!H12 -> 16179 | C10: =base_fleet!M12*0.95 -> 16883.4 | D10: =base_fleet!D12 -> 9 | E10: =base_fleet!R12 -> 18996 | F10: =base_fleet!F12 -> 46 | G10: =base_fleet!K12 -> 125 | H10: =base_fleet!B12 -> 2 | I10: =base_fleet!P12 -> 604 | J10: =base_fleet!C12+base_fleet!G12+base_fleet!L12+base_fleet!Q12 -> 4 | K10: =base_fleet!E12+base_fleet!J12+base_fleet!O12+base_fleet!T12 -> 1619 | L10: =base_fleet!M12*0.05 -> 888.6 | M10: =base_fleet!I12+base_fleet!N12+base_fleet!S12 -> 8 | N10: =base_fleet!AF12 -> 11742 | O10: =base_fleet!AA12 -> 710 | P10: =base_fleet!V12 -> 144 | Q10: =base_fleet!AD12 -> 5850 | R10: =base_fleet!Y12 -> 539 | S10: =base_fleet!U12 -> 344 | T10: =base_fleet!Z12+base_fleet!AE12 -> 0 | U10: =base_fleet!X12+base_fleet!AC12+base_fleet!AH12 -> 32 | V10: =base_fleet!AI12 -> 2385 | W10: =base_fleet!AM12 -> 567 | X10: =base_fleet!AP12 -> 404 | Y10: =base_fleet!AS12 -> 226 | Z10: =base_fleet!AU12 -> 256 | AA10: =base_fleet!AW12 -> 119 | AB10: =base_fleet!AY12/2 -> 4.5 | AC10: =base_fleet!AY12/2 -> 4.5 | AD10: =base_fleet!BB12 -> 15 | AE10: =base_fleet!AK12 -> 39 | AF10: =base_fleet!AO12 -> 5 | AG10: =base_fleet!AR12 -> 1 | AH10: =base_fleet!AT12 -> 3 | AI10: =base_fleet!AV12 -> 0 | AJ10: =base_fleet!AX12 -> 1 | AK10: =base_fleet!AZ12 -> 0 | AL10: =base_fleet!BC12 -> 0 | AM10: 0 | AN10: =base_fleet!BD12 -> 176 | AO10: =base_fleet!BE12 -> 206 | AP10: =base_fleet!BF12 -> 31 | AQ10: =base_fleet!BG12 -> 92 | AR10: =base_fleet!BH12 -> 58 | AS10: =base_fleet!BI12 -> 0 | AT10: =base_fleet!AQ12+base_fleet!AN12+base_fleet!AJ12 -> 0 | AU10: =base_fleet!BL12 -> 609.45 | AV10: =base_fleet!BJ12 -> 37.4 | AW10: =base_fleet!BN12 -> 2.55 | AX10: =base_fleet!BM12 -> 5.95 | AY10: =base_fleet!BK12 -> 0 | AZ10: =base_fleet!BO12 -> 0 | BA10: =base_fleet!BP12 -> 253.2 | BB10: =base_fleet!BR12 -> 4.35 | BC10: =base_fleet!BQ12 -> 0.3 | BD10: =base_fleet!BS12 -> 0 | BE10: 0 | BF10: 0 | BG10: =base_fleet!CE12 -> 1 | BH10: =base_fleet!CA12 -> 18274 | BI10: =base_fleet!BV12 -> 65 | BJ10: =base_fleet!CH12 -> 0 | BK10: =base_fleet!BU12+base_fleet!BZ12+base_fleet!CD12 -> 0
A11: =A10-1 -> 2008 | B11: =base_fleet!H13 -> 13810 | C11: =base_fleet!M13*0.95 -> 12139.1 | D11: =base_fleet!D13 -> 5 | E11: =base_fleet!R13 -> 19637 | F11: =base_fleet!F13 -> 91 | G11: =base_fleet!K13 -> 216 | H11: =base_fleet!B13 -> 1 | I11: =base_fleet!P13 -> 929 | J11: =base_fleet!C13+base_fleet!G13+base_fleet!L13+base_fleet!Q13 -> 8 | K11: =base_fleet!E13+base_fleet!J13+base_fleet!O13+base_fleet!T13 -> 151 | L11: =base_fleet!M13*0.05 -> 638.9 | M11: =base_fleet!I13+base_fleet!N13+base_fleet!S13 -> 3 | N11: =base_fleet!AF13 -> 13093 | O11: =base_fleet!AA13 -> 1279 | P11: =base_fleet!V13 -> 234 | Q11: =base_fleet!AD13 -> 8180 | R11: =base_fleet!Y13 -> 1075 | S11: =base_fleet!U13 -> 477 | T11: =base_fleet!Z13+base_fleet!AE13 -> 2 | U11: =base_fleet!X13+base_fleet!AC13+base_fleet!AH13 -> 22 | V11: =base_fleet!AI13 -> 4624 | W11: =base_fleet!AM13 -> 767 | X11: =base_fleet!AP13 -> 590 | Y11: =base_fleet!AS13 -> 237 | Z11: =base_fleet!AU13 -> 421 | AA11: =base_fleet!AW13 -> 216 | AB11: =base_fleet!AY13/2 -> 13.5 | AC11: =base_fleet!AY13/2 -> 13.5 | AD11: =base_fleet!BB13 -> 31 | AE11: =base_fleet!AK13 -> 58 | AF11: =base_fleet!AO13 -> 10 | AG11: =base_fleet!AR13 -> 3 | AH11: =base_fleet!AT13 -> 3 | AI11: =base_fleet!AV13 -> 3 | AJ11: =base_fleet!AX13 -> 2 | AK11: =base_fleet!AZ13 -> 0 | AL11: =base_fleet!BC13 -> 0 | AM11: 0 | AN11: =base_fleet!BD13 -> 207 | AO11: =base_fleet!BE13 -> 162 | AP11: =base_fleet!BF13 -> 115 | AQ11: =base_fleet!BG13 -> 134 | AR11: =base_fleet!BH13 -> 71 | AS11: =base_fleet!BI13 -> 1 | AT11: =base_fleet!AQ13+base_fleet!AN13+base_fleet!AJ13 -> 0 | AU11: =base_fleet!BL13 -> 1017.45 | AV11: =base_fleet!BJ13 -> 107.95 | AW11: =base_fleet!BN13 -> 16.15 | AX11: =base_fleet!BM13 -> 9.35 | AY11: =base_fleet!BK13 -> 0 | AZ11: =base_fleet!BO13 -> 0 | BA11: =base_fleet!BP13 -> 220.05 | BB11: =base_fleet!BR13 -> 12 | BC11: =base_fleet!BQ13 -> 1.8 | BD11: =base_fleet!BS13 -> 0 | BE11: 0 | BF11: 0 | BG11: =base_fleet!CE13 -> 0 | BH11: =base_fleet!CA13 -> 14436 | BI11: =base_fleet!BV13 -> 100 | BJ11: =base_fleet!CH13 -> 0 | BK11: =base_fleet!BU13+base_fleet!BZ13+base_fleet!CD13 -> 0
A12: =A11-1 -> 2007 | B12: =base_fleet!H14 -> 16222 | C12: =base_fleet!M14*0.95 -> 13208.8 | D12: =base_fleet!D14 -> 13 | E12: =base_fleet!R14 -> 11998 | F12: =base_fleet!F14 -> 125 | G12: =base_fleet!K14 -> 196 | H12: =base_fleet!B14 -> 2 | I12: =base_fleet!P14 -> 955 | J12: =base_fleet!C14+base_fleet!G14+base_fleet!L14+base_fleet!Q14 -> 1 | K12: =base_fleet!E14+base_fleet!J14+base_fleet!O14+base_fleet!T14 -> 1 | L12: =base_fleet!M14*0.05 -> 695.2 | M12: =base_fleet!I14+base_fleet!N14+base_fleet!S14 -> 10 | N12: =base_fleet!AF14 -> 11246 | O12: =base_fleet!AA14 -> 1780 | P12: =base_fleet!V14 -> 207 | Q12: =base_fleet!AD14 -> 3603 | R12: =base_fleet!Y14 -> 815 | S12: =base_fleet!U14 -> 295 | T12: =base_fleet!Z14+base_fleet!AE14 -> 0 | U12: =base_fleet!X14+base_fleet!AC14+base_fleet!AH14 -> 0 | V12: =base_fleet!AI14 -> 4223 | W12: =base_fleet!AM14 -> 616 | X12: =base_fleet!AP14 -> 550 | Y12: =base_fleet!AS14 -> 152 | Z12: =base_fleet!AU14 -> 252 | AA12: =base_fleet!AW14 -> 112 | AB12: =base_fleet!AY14/2 -> 3.5 | AC12: =base_fleet!AY14/2 -> 3.5 | AD12: =base_fleet!BB14 -> 23 | AE12: =base_fleet!AK14 -> 60 | AF12: =base_fleet!AO14 -> 4 | AG12: =base_fleet!AR14 -> 2 | AH12: =base_fleet!AT14 -> 3 | AI12: =base_fleet!AV14 -> 3 | AJ12: =base_fleet!AX14 -> 2 | AK12: =base_fleet!AZ14 -> 0 | AL12: =base_fleet!BC14 -> 0 | AM12: 0 | AN12: =base_fleet!BD14 -> 143 | AO12: =base_fleet!BE14 -> 119 | AP12: =base_fleet!BF14 -> 80 | AQ12: =base_fleet!BG14 -> 54 | AR12: =base_fleet!BH14 -> 49 | AS12: =base_fleet!BI14 -> 0 | AT12: =base_fleet!AQ14+base_fleet!AN14+base_fleet!AJ14 -> 1 | AU12: =base_fleet!BL14 -> 918 | AV12: =base_fleet!BJ14 -> 43.35 | AW12: =base_fleet!BN14 -> 1.7 | AX12: =base_fleet!BM14 -> 6.8 | AY12: =base_fleet!BK14 -> 0.85 | AZ12: =base_fleet!BO14 -> 0 | BA12: =base_fleet!BP14 -> 237.9 | BB12: =base_fleet!BR14 -> 10.8 | BC12: =base_fleet!BQ14 -> 1.8 | BD12: =base_fleet!BS14 -> 0 | BE12: 0 | BF12: 0 | BG12: =base_fleet!CE14 -> 146 | BH12: =base_fleet!CA14 -> 12951 | BI12: =base_fleet!BV14 -> 92 | BJ12: =base_fleet!CH14 -> 1 | BK12: =base_fleet!BU14+base_fleet!BZ14+base_fleet!CD14 -> 0
A13: =A12-1 -> 2006 | B13: =base_fleet!H15 -> 13552 | C13: =base_fleet!M15*0.95 -> 16204.15 | D13: =base_fleet!D15 -> 51 | E13: =base_fleet!R15 -> 12471 | F13: =$B$13/$B$12*F12 -> 104.42609 | G13: =$B$13/$B$12*G12 -> 163.74011 | H13: =$B$13/$B$12*H12 -> 1.6708174 | I13: =base_fleet!P15 -> 1365 | J13: =base_fleet!C15+base_fleet!G15+base_fleet!L15+base_fleet!Q15 -> 1 | K13: =base_fleet!E15+base_fleet!J15+base_fleet!O15+base_fleet!T15 -> 2 | L13: =base_fleet!M15*0.05 -> 852.85 | M13: =base_fleet!I15+base_fleet!N15+base_fleet!S15 -> 25 | N13: =base_fleet!AF15 -> 12755 | O13: =base_fleet!AA15 -> 1521 | P13: =base_fleet!V15 -> 197 | Q13: =base_fleet!AD15 -> 2611 | R13: =base_fleet!Y15 -> 342 | S13: =base_fleet!U15 -> 206 | T13: =base_fleet!Z15+base_fleet!AE15 -> 0 | U13: =base_fleet!X15+base_fleet!AC15+base_fleet!AH15 -> 0 | V13: =base_fleet!AI15 -> 4542 | W13: =base_fleet!AM15 -> 633 | X13: =base_fleet!AP15 -> 313 | Y13: =base_fleet!AS15 -> 117 | Z13: =base_fleet!AU15 -> 195 | AA13: =base_fleet!AW15 -> 36 | AB13: =base_fleet!AY15/2 -> 0.5 | AC13: =base_fleet!AY15/2 -> 0.5 | AD13: =base_fleet!BB15 -> 14 | AE13: =base_fleet!AK15 -> 71 | AF13: =base_fleet!AO15 -> 7 | AG13: =base_fleet!AR15 -> 3 | AH13: =base_fleet!AT15 -> 2 | AI13: =base_fleet!AV15 -> 5 | AJ13: =base_fleet!AX15 -> 0 | AK13: =base_fleet!AZ15 -> 0 | AL13: =base_fleet!BC15 -> 0 | AM13: 0 | AN13: =base_fleet!BD15 -> 100 | AO13: =base_fleet!BE15 -> 57 | AP13: =base_fleet!BF15 -> 41 | AQ13: =base_fleet!BG15 -> 44 | AR13: =base_fleet!BH15 -> 58 | AS13: =base_fleet!BI15 -> 0 | AT13: =base_fleet!AQ15+base_fleet!AN15+base_fleet!AJ15 -> 0 | AU13: =base_fleet!BL15 -> 729.3 | AV13: =base_fleet!BJ15 -> 189.55 | AW13: =base_fleet!BN15 -> 7.65 | AX13: =base_fleet!BM15 -> 7.65 | AY13: =base_fleet!BK15 -> 0 | AZ13: =base_fleet!BO15 -> 0 | BA13: =base_fleet!BP15 -> 179.1 | BB13: =base_fleet!BR15 -> 3 | BC13: =base_fleet!BQ15 -> 0.3 | BD13: =base_fleet!BS15 -> 0 | BE13: 0 | BF13: 0 | BG13: =base_fleet!CE15 -> 834 | BH13: =base_fleet!CA15 -> 8597 | BI13: =base_fleet!BV15 -> 78 | BJ13: =base_fleet!CH15 -> 0 | BK13: =base_fleet!BU15+base_fleet!BZ15+base_fleet!CD15 -> 0
A14: =A13-1 -> 2005 | B14: =$B$13/$B$12*B13 -> 11321.459 | C14: =base_fleet!M16*0.95 -> 24537.55 | D14: =base_fleet!D16 -> 10 | E14: =base_fleet!R16 -> 8744 | F14: =$B$13/$B$12*F13 -> 87.238463 | G14: =$B$13/$B$12*G13 -> 136.78991 | H14: =$B$13/$B$12*H13 -> 1.3958154 | I14: =base_fleet!P16 -> 1080 | J14: =base_fleet!C16+base_fleet!G16+base_fleet!L16+base_fleet!Q16 -> 0 | K14: =base_fleet!E16+base_fleet!J16+base_fleet!O16+base_fleet!T16 -> 0 | L14: =base_fleet!M16*0.05 -> 1291.45 | M14: =base_fleet!I16+base_fleet!N16+base_fleet!S16 -> 6 | N14: =base_fleet!AF16 -> 11361 | O14: =base_fleet!AA16 -> 906 | P14: =base_fleet!V16 -> 429 | Q14: =base_fleet!AD16 -> 2421 | R14: =base_fleet!Y16 -> 232 | S14: =base_fleet!U16 -> 101 | T14: =base_fleet!Z16+base_fleet!AE16 -> 0 | U14: =base_fleet!X16+base_fleet!AC16+base_fleet!AH16 -> 1 | V14: =base_fleet!AI16 -> 3215 | W14: =base_fleet!AM16 -> 673 | X14: =base_fleet!AP16 -> 151 | Y14: =base_fleet!AS16 -> 114 | Z14: =base_fleet!AU16 -> 228 | AA14: =base_fleet!AW16 -> 45 | AB14: =base_fleet!AY16/2 -> 1.5 | AC14: =base_fleet!AY16/2 -> 1.5 | AD14: =base_fleet!BB16 -> 13 | AE14: =base_fleet!AK16 -> 65 | AF14: =base_fleet!AO16 -> 8 | AG14: =base_fleet!AR16 -> 0 | AH14: =base_fleet!AT16 -> 2 | AI14: =base_fleet!AV16 -> 2 | AJ14: =base_fleet!AX16 -> 0 | AK14: =base_fleet!AZ16 -> 0 | AL14: =base_fleet!BC16 -> 0 | AM14: 0 | AN14: =base_fleet!BD16 -> 107 | AO14: =base_fleet!BE16 -> 89 | AP14: =base_fleet!BF16 -> 17 | AQ14: =base_fleet!BG16 -> 49 | AR14: =base_fleet!BH16 -> 30 | AS14: =base_fleet!BI16 -> 1 | AT14: =base_fleet!AQ16+base_fleet!AN16+base_fleet!AJ16 -> 1 | AU14: =base_fleet!BL16 -> 901 | AV14: =base_fleet!BJ16 -> 368.9 | AW14: =base_fleet!BN16 -> 0.85 | AX14: =base_fleet!BM16 -> 9.35 | AY14: =base_fleet!BK16 -> 0.85 | AZ14: =base_fleet!BO16 -> 0 | BA14: =base_fleet!BP16 -> 267 | BB14: =base_fleet!BR16 -> 11.7 | BC14: =base_fleet!BQ16 -> 0.6 | BD14: =base_fleet!BS16 -> 0 | BE14: 0 | BF14: 0 | BG14: =base_fleet!CE16 -> 1079 | BH14: =base_fleet!CA16 -> 8126 | BI14: =base_fleet!BV16 -> 55 | BJ14: =base_fleet!CH16 -> 1 | BK14: =base_fleet!BU16+base_fleet!BZ16+base_fleet!CD16 -> 0
A15: =A14-1 -> 2004 | B15: =$B$13/$B$12*B14 -> 9458.0452 | C15: =base_fleet!M17*0.95 -> 16937.55 | D15: =base_fleet!D17 -> 10 | E15: =base_fleet!R17 -> 7739 | F15: =$B$13/$B$12*F14 -> 72.879771 | G15: =$B$13/$B$12*G14 -> 114.27548 | H15: =$B$13/$B$12*H14 -> 1.1660763 | I15: =$B$13/$B$12*I14 -> 902.2414 | J15: =base_fleet!C17+base_fleet!G17+base_fleet!L17+base_fleet!Q17 -> 0 | K15: =base_fleet!E17+base_fleet!J17+base_fleet!O17+base_fleet!T17 -> 0 | L15: =$B$13/$B$12*L14 -> 1078.8886 | M15: =base_fleet!I17+base_fleet!N17 -> 0 | N15: =base_fleet!AF17 -> 10904 | O15: =base_fleet!AA17 -> 171 | P15: =base_fleet!V17 -> 763 | Q15: =base_fleet!AD17 -> 2084 | R15: =base_fleet!Y17 -> 296 | S15: =base_fleet!U17 -> 112 | T15: =base_fleet!Z17+base_fleet!AE17 -> 0 | U15: =base_fleet!X17+base_fleet!AC17+base_fleet!AH17 -> 0 | V15: =$B$13/$B$12*V14 -> 2685.839 | W15: =$B$13/$B$12*W14 -> 562.23006 | X15: =$B$13/$B$12*X14 -> 126.14671 | Y15: =$B$13/$B$12*Y14 -> 95.236592 | Z15: =$B$13/$B$12*Z14 -> 190.47318 | AA15: =$B$13/$B$12*AA14 -> 37.593392 | AB15: =$B$13/$B$12*AB14 -> 1.2531131 | AC15: =$B$13/$B$12*AC14 -> 1.2531131 | ... AS15: =$B$13/$B$12*AS14 -> 0.8354087 | AT15: =base_fleet!AQ17+base_fleet!AN17+base_fleet!AJ17 -> 0 | AU15: =base_fleet!BL17 -> 994.5 | AV15: =base_fleet!BJ17 -> 238.85 | AW15: =base_fleet!BN17 -> 25.5 | AX15: =base_fleet!BM17 -> 10.2 | AY15: =base_fleet!BK17 -> 0 | AZ15: =base_fleet!BO17 -> 0 | BA15: =base_fleet!BP17 -> 237.75 | BB15: =base_fleet!BR17 -> 21.75 | BC15: =base_fleet!BQ17 -> 0.6 | BD15: =base_fleet!BS17 -> 0.15 | BE15: 0 | BF15: 0 | BG15: =base_fleet!CE17 -> 494 | BH15: =base_fleet!CA17 -> 3843 | BI15: =base_fleet!BV17 -> 30 | BJ15: =base_fleet!CH17 -> 0 | BK15: =base_fleet!BU17+base_fleet!BZ17+base_fleet!CD17 -> 0
A16: =A15-1 -> 2003 | B16: =$B$13/$B$12*B15 -> 7901.3333 | C16: =$B$13/$B$12*C15 -> 14149.777 | D16: =$B$13/$B$12*D15 -> 8.354087 | E16: =base_fleet!R18 -> 5891 | F16: =$B$13/$B$12*F15 -> 60.884395 | G16: =$B$13/$B$12*G15 -> 95.466732 | H16: =$B$13/$B$12*H15 -> 0.97415032 | I16: =$B$13/$B$12*I15 -> 753.74032 | J16: =base_fleet!C18+base_fleet!G18+base_fleet!L18+base_fleet!Q18 -> 0 | K16: =base_fleet!E18+base_fleet!J18+base_fleet!O18+base_fleet!T18 -> 0 | L16: =$B$13/$B$12*L15 -> 901.3129 | M16: =base_fleet!I18+base_fleet!N18 -> 0 | N16: =$B$13/$B$12*N15 -> 9109.2965 | O16: =$B$13/$B$12*O15 -> 142.85489 | P16: =$B$13/$B$12*P15 -> 637.41684 | Q16: =$B$13/$B$12*Q15 -> 1740.9917 | R16: =$B$13/$B$12*R15 -> 247.28098 | S16: =$B$13/$B$12*S15 -> 93.565775 | T16: =base_fleet!Z18+base_fleet!AE18 -> 1 | U16: =base_fleet!X18+base_fleet!AC18+base_fleet!AH18 -> 0 | V16: =$B$13/$B$12*V15 -> 2243.7733 | W16: =$B$13/$B$12*W15 -> 469.69188 | X16: =$B$13/$B$12*X15 -> 105.38406 | Y16: =$B$13/$B$12*Y15 -> 79.561478 | Z16: =$B$13/$B$12*Z15 -> 159.12296 | AA16: =$B$13/$B$12*AA15 -> 31.405847 | AB16: =$B$13/$B$12*AB15 -> 1.0468616 | AC16: =$B$13/$B$12*AC15 -> 1.0468616 | ... AS16: =$B$13/$B$12*AS15 -> 0.6979077 | AT16: =base_fleet!AQ18+base_fleet!AN18+base_fleet!AJ18 -> 0 | AU16: =base_fleet!BL18 -> 957.1 | AV16: =base_fleet!BJ18 -> 87.55 | AW16: =base_fleet!BN18 -> 29.75 | AX16: =base_fleet!BM18 -> 11.05 | AY16: =base_fleet!BK18 -> 0 | AZ16: =base_fleet!BO18 -> 0.85 | BA16: =$B$13/$B$12*BA15 -> 198.61842 | BB16: =$B$13/$B$12*BB15 -> 18.170139 | BC16: =$B$13/$B$12*BC15 -> 0.50124522 | BD16: =$B$13/$B$12*BD15 -> 0.12531131 | BE16: 0 | BF16: 0 | BG16: =base_fleet!CE18 -> 449 | BH16: =base_fleet!CA18 -> 3085 | BI16: =base_fleet!BV18 -> 19 | BJ16: =base_fleet!CH18 -> 0 | BK16: =base_fleet!BU18+base_fleet!BZ18+base_fleet!CD18 -> 0
A17: =A16-1 -> 2002 | B17: =$B$13/$B$12*B16 -> 6600.8426 | C17: =$B$13/$B$12*C16 -> 11820.847 | D17: =$B$13/$B$12*D16 -> 6.979077 | E17: =$B$13/$B$12*E16 -> 4921.3927 | F17: =$B$13/$B$12*F16 -> 50.863354 | G17: =$B$13/$B$12*G16 -> 79.753739 | H17: =$B$13/$B$12*H16 -> 0.81381366 | I17: =$B$13/$B$12*I16 -> 629.68122 | J17: =base_fleet!C19+base_fleet!G19+base_fleet!L19+base_fleet!Q19 -> 0 | K17: =base_fleet!E19+base_fleet!J19+base_fleet!O19+base_fleet!T19 -> 0 | L17: =$B$13/$B$12*L16 -> 752.96464 | M17: =base_fleet!I19+base_fleet!N19 -> 0 | N17: =$B$13/$B$12*N16 -> 7609.9856 | O17: =$B$13/$B$12*O16 -> 119.34222 | P17: =$B$13/$B$12*P16 -> 532.50358 | Q17: =$B$13/$B$12*Q16 -> 1454.4397 | R17: =$B$13/$B$12*R16 -> 206.58068 | S17: =$B$13/$B$12*S16 -> 78.165663 | T17: =base_fleet!Z19+base_fleet!AE19 -> 0 | U17: =base_fleet!X19+base_fleet!AC19+base_fleet!AH19 -> 0 | V17: =$B$13/$B$12*V16 -> 1874.4677 | W17: =$B$13/$B$12*W16 -> 392.38469 | X17: =$B$13/$B$12*X16 -> 88.038764 | Y17: =$B$13/$B$12*Y16 -> 66.466351 | Z17: =$B$13/$B$12*Z16 -> 132.9327 | AA17: =$B$13/$B$12*AA16 -> 26.236718 | AB17: =$B$13/$B$12*AB16 -> 0.87455725 | AC17: =$B$13/$B$12*AC16 -> 0.87455725 | ... AS17: =$B$13/$B$12*AS16 -> 0.58303817 | AT17: =base_fleet!AQ19+base_fleet!AN19+base_fleet!AJ19 -> 0 | AU17: =$B$13/$B$12*AU16 -> 799.56967 | AV17: =$B$13/$B$12*AV16 -> 73.140032 | AW17: =$B$13/$B$12*AW16 -> 24.853409 | AX17: =$B$13/$B$12*AX16 -> 9.2312662 | AY17: =$B$13/$B$12*AY16 -> 0 | AZ17: =$B$13/$B$12*AZ16 -> 0.7100974 | BA17: =$B$13/$B$12*BA16 -> 165.92756 | BB17: =$B$13/$B$12*BB16 -> 15.179493 | ... BD17: =$B$13/$B$12*BD16 -> 0.10468616 | BE17: 0 | BF17: 0 | BG17: =base_fleet!CE19 -> 0 | BH17: =base_fleet!CA19 -> 0 | BI17: =base_fleet!BV19 -> 0 | BJ17: =base_fleet!CH19 -> 0 | BK17: =base_fleet!BU19+base_fleet!BZ19+base_fleet!CD19 -> 0
A18: =A17-1 -> 2001 | B18: =$B$13/$B$12*B17 -> 5514.4014 | C18: =$B$13/$B$12*C17 -> 9875.2382 | D18: =$B$13/$B$12*D17 -> 5.8303817 | E18: =$B$13/$B$12*E17 -> 4111.3743 | F18: =$B$13/$B$12*F17 -> 42.491688 | G18: =$B$13/$B$12*G17 -> 66.626967 | H18: =$B$13/$B$12*H17 -> 0.67986702 | I18: =$B$13/$B$12*I17 -> 526.04118 | J18: =base_fleet!C20+base_fleet!G20+base_fleet!L20+base_fleet!Q20 -> 0 | K18: =base_fleet!E20+base_fleet!J20+base_fleet!O20+base_fleet!T20 -> 0 | L18: =$B$13/$B$12*L17 -> 629.03322 | M18: =base_fleet!I20+base_fleet!N20 -> 0 | N18: =$B$13/$B$12*N17 -> 6357.4482 | O18: =$B$13/$B$12*O17 -> 99.699527 | P18: =$B$13/$B$12*P17 -> 444.85812 | Q18: =$B$13/$B$12*Q17 -> 1215.0515 | R18: =$B$13/$B$12*R17 -> 172.5793 | S18: =$B$13/$B$12*S17 -> 65.300275 | T18: =base_fleet!Z20+base_fleet!AE20 -> 0 | U18: =base_fleet!X20+base_fleet!AC20+base_fleet!AH20 -> 0 | V18: =$B$13/$B$12*V17 -> 1565.9466 | W18: =$B$13/$B$12*W17 -> 327.80158 | X18: =$B$13/$B$12*X17 -> 73.548349 | Y18: =$B$13/$B$12*Y17 -> 55.526568 | Z18: =$B$13/$B$12*Z17 -> 111.05314 | AA18: =$B$13/$B$12*AA17 -> 21.918382 | AB18: =$B$13/$B$12*AB17 -> 0.73061274 | AC18: =$B$13/$B$12*AC17 -> 0.73061274 | ... AS18: =$B$13/$B$12*AS17 -> 0.48707516 | AT18: =base_fleet!AQ20+base_fleet!AN20+base_fleet!AJ20 -> 0 | AU18: =$B$13/$B$12*AU17 -> 667.96746 | AV18: =$B$13/$B$12*AV17 -> 61.101819 | AW18: =$B$13/$B$12*AW17 -> 20.762754 | AX18: =$B$13/$B$12*AX17 -> 7.7118801 | AY18: =$B$13/$B$12*AY17 -> 0 | AZ18: =$B$13/$B$12*AZ17 -> 0.59322155 | BA18: =$B$13/$B$12*BA17 -> 138.61732 | BB18: =$B$13/$B$12*BB17 -> 12.68108 | ... BD18: =$B$13/$B$12*BD17 -> 0.087455725 | BE18: 0 | BF18: 0 | BG18: =base_fleet!CE20 -> 0 | BH18: =base_fleet!CA20 -> 0 | BI18: =base_fleet!BV20 -> 0 | BJ18: =base_fleet!CH20 -> 0 | BK18: =base_fleet!BU20+base_fleet!BZ20+base_fleet!CD20 -> 0
A19: =A18-1 -> 2000 | B19: =$B$13/$B$12*B18 -> 4606.7789 | C19: =$B$13/$B$12*C18 -> 8249.8599 | D19: =$B$13/$B$12*D18 -> 4.8707516 | E19: =$B$13/$B$12*E18 -> 3434.6779 | F19: =$B$13/$B$12*F18 -> 35.497926 | G19: =$B$13/$B$12*G18 -> 55.660749 | H19: =$B$13/$B$12*H18 -> 0.56796682 | I19: =$B$13/$B$12*I18 -> 439.45938 | J19: =base_fleet!C21+base_fleet!G21+base_fleet!L21+base_fleet!Q21 -> 0 | K19: =base_fleet!E21+base_fleet!J21+base_fleet!O21+base_fleet!T21 -> 0 | L19: =$B$13/$B$12*L18 -> 525.49983 | M19: =base_fleet!I21+base_fleet!N21 -> 0 | N19: =$B$13/$B$12*N18 -> 5311.0676 | O19: =$B$13/$B$12*O18 -> 83.289853 | P19: =$B$13/$B$12*P18 -> 371.63835 | Q19: =$B$13/$B$12*Q18 -> 1015.0646 | R19: =$B$13/$B$12*R18 -> 144.17425 | S19: =$B$13/$B$12*S18 -> 54.552418 | T19: =base_fleet!Z21+base_fleet!AE21 -> 0 | U19: =base_fleet!X21+base_fleet!AC21+base_fleet!AH21 -> 0 | V19: =$B$13/$B$12*V18 -> 1308.2055 | W19: =$B$13/$B$12*W18 -> 273.8483 | X19: =$B$13/$B$12*X18 -> 61.442931 | Y19: =$B$13/$B$12*Y18 -> 46.387379 | Z19: =$B$13/$B$12*Z18 -> 92.774757 | AA19: =$B$13/$B$12*AA18 -> 18.310807 | AB19: =$B$13/$B$12*AB18 -> 0.61036024 | AC19: =$B$13/$B$12*AC18 -> 0.61036024 | ... AS19: =$B$13/$B$12*AS18 -> 0.40690683 | AT19: =base_fleet!AQ21+base_fleet!AN21+base_fleet!AJ21 -> 0 | AU19: =$B$13/$B$12*AU18 -> 558.02583 | AV19: =$B$13/$B$12*AV18 -> 51.044992 | AW19: =$B$13/$B$12*AW18 -> 17.345386 | AX19: =$B$13/$B$12*AX18 -> 6.4425718 | AY19: =$B$13/$B$12*AY18 -> 0 | AZ19: =$B$13/$B$12*AZ18 -> 0.49558244 | BA19: =$B$13/$B$12*BA18 -> 115.80212 | BB19: =$B$13/$B$12*BB18 -> 10.593885 | ... BD19: =$B$13/$B$12*BD18 -> 0.073061274 | BE19: 0 | BF19: 0 | BG19: =base_fleet!CE21 -> 0 | BH19: =base_fleet!CA21 -> 0 | BI19: =base_fleet!BV21 -> 0 | BJ19: =base_fleet!CH21 -> 0 | BK19: =base_fleet!BU21+base_fleet!BZ21+base_fleet!CD21 -> 0
A20: =A19-1 -> 1999 | B20: =$B$13/$B$12*B19 -> 3848.5432 | C20: =$B$13/$B$12*C19 -> 6892.0048 | D20: =$B$13/$B$12*D19 -> 4.0690683 | E20: =$B$13/$B$12*E19 -> 2869.3598 | F20: =$B$13/$B$12*F19 -> 29.655277 | G20: =$B$13/$B$12*G19 -> 46.499474 | H20: =$B$13/$B$12*H19 -> 0.47448443 | I20: =$B$13/$B$12*I19 -> 367.12819 | J20: =base_fleet!C22+base_fleet!G22+base_fleet!L22+base_fleet!Q22 -> 0 | K20: =base_fleet!E22+base_fleet!J22+base_fleet!O22+base_fleet!T22 -> 0 | L20: =$B$13/$B$12*L19 -> 439.00713 | M20: =base_fleet!I22+base_fleet!N22 -> 0 | N20: =$B$13/$B$12*N19 -> 4436.9121 | O20: =$B$13/$B$12*O19 -> 69.581068 | P20: =$B$13/$B$12*P19 -> 310.46991 | Q20: =$B$13/$B$12*Q19 -> 847.99383 | R20: =$B$13/$B$12*R19 -> 120.44442 | S20: =$B$13/$B$12*S19 -> 45.573565 | T20: =base_fleet!Z22+base_fleet!AE22 -> 0 | U20: =base_fleet!X22+base_fleet!AC22+base_fleet!AH22 -> 0 | V20: =$B$13/$B$12*V19 -> 1092.8862 | W20: =$B$13/$B$12*W19 -> 228.77525 | X20: =$B$13/$B$12*X19 -> 51.32996 | Y20: =$B$13/$B$12*Y19 -> 38.75242 | Z20: =$B$13/$B$12*Z19 -> 77.50484 | AA20: =$B$13/$B$12*AA19 -> 15.297008 | AB20: =$B$13/$B$12*AB19 -> 0.50990026 | AC20: =$B$13/$B$12*AC19 -> 0.50990026 | ... AS20: =$B$13/$B$12*AS19 -> 0.33993351 | AT20: =base_fleet!AQ22+base_fleet!AN22+base_fleet!AJ22 -> 0 | AU20: =$B$13/$B$12*AU19 -> 466.17964 | AV20: =$B$13/$B$12*AV19 -> 42.64343 | AW20: =$B$13/$B$12*AW19 -> 14.490486 | AX20: =$B$13/$B$12*AX19 -> 5.3821805 | AY20: =$B$13/$B$12*AY19 -> 0 | AZ20: =$B$13/$B$12*AZ19 -> 0.41401389 | BA20: =$B$13/$B$12*BA19 -> 96.742099 | BB20: =$B$13/$B$12*BB19 -> 8.8502236 | ... BD20: =$B$13/$B$12*BD19 -> 0.061036024 | BE20: 0 | BF20: 0 | BG20: =base_fleet!CE22 -> 0 | BH20: =base_fleet!CA22 -> 0 | BI20: =base_fleet!BV22 -> 0 | BJ20: =base_fleet!CH22 -> 0 | BK20: =base_fleet!BU22+base_fleet!BZ22+base_fleet!CD22 -> 0
