Workbook

Sheet metadata
A1: family | B1: vehicles | C1: name | D1: fuel | E1: size | F1: trips_day | G1: survival | H1: survival_param_a | I1: survival_param_b | J1: sppm | K1: Category_EEA | L1: Fuel_EEA | M1: Segment_EEA | N1: Mode_EEA | O1: Slope_EEA | P1: Load_EEA | Q1: speed | R1: driving_cycle | S1: km_cycle | T1: note | U1: v_eea_old | V1: t_eea_old | W1: cc_eea_old | X1: fuel_eea_old
A2: PC | B2: PC_MINI_G | C2: Passenger cars mini with gasoline | D2: G | E2: <1400cc | F2: 4.5 | G2: gompertz | H2: 1.798 | I2: -0.137 | J2: =IF(D2="D", 250, 50) -> 50 | K2: Passenger Cars | L2: =IF(D2="G","Petrol",IF(D2="D","Diesel",IF(D2="HY","Petrol Hybrid",IF(D2="GLP","LPG Bifuell ~ LPG",D2)))) -> Petrol | M2: Small | Q2: 34.2 | R2: FTP-75 | S2: 17.787 | U2: PC | V2: 4S | W2: <=1400 | X2: =D2 -> G
A3: PC | B3: PC_SMALL_G | C3: Passenger cars small with gasoline | D3: G | E3: 1400-2000cc | F3: 4.5 | G3: gompertz | H3: 1.798 | I3: -0.137 | J3: =IF(D3="D", 250, 50) -> 50 | K3: Passenger Cars | L3: =IF(D3="G","Petrol",IF(D3="D","Diesel",IF(D3="HY","Petrol Hybrid",IF(D3="GLP","LPG Bifuell ~ LPG",D3)))) -> Petrol | M3: Small | Q3: 34.2 | R3: FTP-75 | S3: 17.787 | U3: PC | V3: 4S | W3: <=1400 | X3: =D3 -> G
A4: PC | B4: PC_MEDIUM_G | C4: Passenger cars medium with gasoline | D4: G | E4: >2000cc | F4: 4.5 | G4: gompertz | H4: 1.798 | I4: -0.137 | J4: =IF(D4="D", 250, 50) -> 50 | K4: Passenger Cars | L4: =IF(D4="G","Petrol",IF(D4="D","Diesel",IF(D4="HY","Petrol Hybrid",IF(D4="GLP","LPG Bifuell ~ LPG",D4)))) -> Petrol | M4: Medium | Q4: 34.2 | R4: FTP-75 | S4: 17.787 | U4: PC | V4: 4S | W4: 1400_2000 | X4: =D4 -> G
A5: PC | B5: PC_SUV_G | C5: Sport utility vehicle with gasoline | D5: G | E5: >1400cc | F5: 4.5 | G5: gompertz | H5: 1.798 | I5: -0.137 | J5: =IF(D5="D", 250, 50) -> 50 | K5: Passenger Cars | L5: =IF(D5="G","Petrol",IF(D5="D","Diesel",IF(D5="HY","Petrol Hybrid",IF(D5="GLP","LPG Bifuell ~ LPG",D5)))) -> Petrol | M5: Large-SUV-Executive | Q5: 34.2 | R5: FTP-75 | S5: 17.787 | U5: PC | V5: 4S | W5: >2000 | X5: =D5 -> G
A6: PC | B6: PC_MINI_D | C6: Passenger cars mini with gasoline | D6: D | E6: <1400cc | F6: 4.5 | G6: gompertz | H6: 1.798 | I6: -0.137 | J6: =IF(D6="D", 250, 50) -> 250 | K6: Passenger Cars | L6: =IF(D6="G","Petrol",IF(D6="D","Diesel",IF(D6="HY","Petrol Hybrid",IF(D6="GLP","LPG Bifuell ~ LPG",D6)))) -> Diesel | M6: Small | Q6: 34.2 | R6: FTP-75 | S6: 17.787 | U6: PC | V6: 4S | W6: <=1400 | X6: =D6 -> D
A7: PC | B7: PC_SMALL_D | C7: Passenger cars small with gasoline | D7: D | E7: 1400-2000cc | F7: 4.5 | G7: gompertz | H7: 1.798 | I7: -0.137 | J7: =IF(D7="D", 250, 50) -> 250 | K7: Passenger Cars | L7: =IF(D7="G","Petrol",IF(D7="D","Diesel",IF(D7="HY","Petrol Hybrid",IF(D7="GLP","LPG Bifuell ~ LPG",D7)))) -> Diesel | M7: Small | Q7: 34.2 | R7: FTP-75 | S7: 17.787 | U7: PC | V7: 4S | W7: <=1400 | X7: =D7 -> D
A8: PC | B8: PC_MEDIUM_D | C8: Passenger cars medium with gasoline | D8: D | E8: >2000cc | F8: 4.5 | G8: gompertz | H8: 1.798 | I8: -0.137 | J8: =IF(D8="D", 250, 50) -> 250 | K8: Passenger Cars | L8: =IF(D8="G","Petrol",IF(D8="D","Diesel",IF(D8="HY","Petrol Hybrid",IF(D8="GLP","LPG Bifuell ~ LPG",D8)))) -> Diesel | M8: Medium | Q8: 34.2 | R8: FTP-75 | S8: 17.787 | U8: PC | V8: 4S | W8: 1400_2000 | X8: =D8 -> D
A9: PC | B9: PC_SUV_D | C9: Sport utility vehicle with gasoline | D9: D | E9: >1400cc | F9: 4.5 | G9: gompertz | H9: 1.798 | I9: -0.137 | J9: =IF(D9="D", 250, 50) -> 250 | K9: Passenger Cars | L9: =IF(D9="G","Petrol",IF(D9="D","Diesel",IF(D9="HY","Petrol Hybrid",IF(D9="GLP","LPG Bifuell ~ LPG",D9)))) -> Diesel | M9: Large-SUV-Executive | Q9: 34.2 | R9: FTP-75 | S9: 17.787 | U9: PC | V9: 4S | W9: >2000 | X9: =D9 -> D
A10: PC | B10: PC_ELEC | C10: Passenger cars electric | D10: ELEC | E10: all | F10: 4.5 | G10: gompertz | H10: 1.798 | I10: -0.137 | J10: =IF(D10="D", 250, 50) -> 50 | K10: Passenger Cars | L10: =IF(D10="G","Petrol",IF(D10="D","Diesel",IF(D10="HY","Petrol Hybrid",IF(D10="GLP","LPG Bifuell ~ LPG",D10)))) -> ELEC | M10: Small | Q10: 34.2 | R10: FTP-75 | S10: 17.787 | U10: PC | V10: 4S | W10: <=1400 | X10: =D10 -> ELEC
A11: PC | B11: PC_SMALL_HY | C11: Passenger cars small with gasoline | D11: HY | E11: 1400-2000cc | F11: 4.5 | G11: gompertz | H11: 1.798 | I11: -0.137 | J11: =IF(D11="D", 250, 50) -> 50 | K11: Passenger Cars | L11: =IF(D11="G","Petrol",IF(D11="D","Diesel",IF(D11="HY","Petrol Hybrid",IF(D11="GLP","LPG Bifuell ~ LPG",D11)))) -> Petrol Hybrid | M11: Small | Q11: 34.2 | R11: FTP-75 | S11: 17.787 | U11: PC | V11: 4S | W11: 1400_2000 | X11: FH
A12: PC | B12: TAXI_SMALL_G | C12: Taxi small with gasoline | D12: G | E12: 1400-2000cc | F12: 4.5 | G12: gompertz | H12: 1.798 | I12: -0.137 | J12: =IF(D12="D", 250, 50) -> 50 | K12: Passenger Cars | L12: =IF(D12="G","Petrol",IF(D12="D","Diesel",IF(D12="HY","Petrol Hybrid",IF(D12="GLP","LPG Bifuell ~ LPG",D12)))) -> Petrol | M12: Small | Q12: 34.2 | R12: FTP-75 | S12: 17.787 | U12: PC | V12: 4S | W12: 1400_2000 | X12: =D12 -> G
A13: PC | B13: TAXI_SMALL_GLP | C13: Taxi small with glp | D13: GLP | E13: 1400-2000cc | F13: 4.5 | G13: gompertz | H13: 1.798 | I13: -0.137 | J13: =IF(D13="D", 250, 50) -> 50 | K13: Passenger Cars | L13: =IF(D13="G","Petrol",IF(D13="D","Diesel",IF(D13="HY","Petrol Hybrid",IF(D13="GLP","LPG Bifuell ~ LPG",D13)))) -> LPG Bifuell ~ LPG | M13: Small | Q13: 34.2 | R13: FTP-75 | S13: 17.787 | U13: PC | V13: 4S | W13: 1400_2000 | X13: LPG
A14: LCV | B14: LCV_NI_G | C14: Light commercial vehicles N1 with gasoline | D14: G | E14: <=1.305t | F14: 4.5 | G14: gompertz | H14: 1.618 | I14: -0.141 | J14: =IF(D14="D", 250, 50) -> 50 | K14: Light Commercial Vehicles | L14: =IF(D14="G","Petrol",IF(D14="D","Diesel",IF(D14="HY","Petrol Hybrid",IF(D14="GLP","LPG Bifuell ~ LPG",D14)))) -> Petrol | M14: N1-I | Q14: 34.2 | R14: FTP-75 | S14: 17.787 | U14: LCV | V14: 4S | W14: <3.5 | X14: =D14 -> G
A15: LCV | B15: LCV_NII_G | C15: Light commercial vehicles N2 with gasoline | D15: G | E15: 1.305-1.76t | F15: 4.5 | G15: gompertz | H15: 1.618 | I15: -0.141 | J15: =IF(D15="D", 250, 50) -> 50 | K15: Light Commercial Vehicles | L15: =IF(D15="G","Petrol",IF(D15="D","Diesel",IF(D15="HY","Petrol Hybrid",IF(D15="GLP","LPG Bifuell ~ LPG",D15)))) -> Petrol | M15: N1-II | Q15: 34.2 | R15: FTP-75 | S15: 17.787 | U15: LCV | V15: 4S | W15: <3.5 | X15: =D15 -> G
A16: LCV | B16: LCV_NIII_G | C16: Light commercial vehicles N3 with gasoline | D16: G | E16: >=1.76t | F16: 4.5 | G16: gompertz | H16: 1.618 | I16: -0.141 | J16: =IF(D16="D", 250, 50) -> 50 | K16: Light Commercial Vehicles | L16: =IF(D16="G","Petrol",IF(D16="D","Diesel",IF(D16="HY","Petrol Hybrid",IF(D16="GLP","LPG Bifuell ~ LPG",D16)))) -> Petrol | M16: N1-III | Q16: 34.2 | R16: FTP-75 | S16: 17.787 | U16: LCV | V16: 4S | W16: <3.5 | X16: =D16 -> G
A17: LCV | B17: LCV_NI_D | C17: Light commercial vehicles N1 with diesel | D17: D | E17: <=1.305t | F17: 4.5 | G17: double_logistic | H17: 0.1 | I17: 17 | J17: =IF(D17="D", 250, 50) -> 250 | K17: Light Commercial Vehicles | L17: =IF(D17="G","Petrol",IF(D17="D","Diesel",IF(D17="HY","Petrol Hybrid",IF(D17="GLP","LPG Bifuell ~ LPG",D17)))) -> Diesel | M17: N1-I | Q17: 34.2 | R17: FTP-75 | S17: 17.787 | U17: LCV | V17: 4S | W17: <3.5 | X17: =D17 -> D
A18: LCV | B18: LCV_NII_D | C18: Light commercial vehicles N2 with diesel | D18: D | E18: 1.305-1.76t | F18: 4.5 | G18: double_logistic | H18: 0.1 | I18: 17 | J18: =IF(D18="D", 250, 50) -> 250 | K18: Light Commercial Vehicles | L18: =IF(D18="G","Petrol",IF(D18="D","Diesel",IF(D18="HY","Petrol Hybrid",IF(D18="GLP","LPG Bifuell ~ LPG",D18)))) -> Diesel | M18: N1-II | Q18: 34.2 | R18: FTP-75 | S18: 17.787 | U18: LCV | V18: 4S | W18: <3.5 | X18: =D18 -> D
A19: LCV | B19: LCV_NIII_D | C19: Light commercial vehicles N3 with diesel | D19: D | E19: >=1.76t | F19: 4.5 | G19: double_logistic | H19: 0.1 | I19: 17 | J19: =IF(D19="D", 250, 50) -> 250 | K19: Light Commercial Vehicles | L19: =IF(D19="G","Petrol",IF(D19="D","Diesel",IF(D19="HY","Petrol Hybrid",IF(D19="GLP","LPG Bifuell ~ LPG",D19)))) -> Diesel | M19: N1-III | Q19: 34.2 | R19: FTP-75 | S19: 17.787 | U19: LCV | V19: 4S | W19: <3.5 | X19: =D19 -> D
A20: LCV | B20: LCV_ELEC | C20: Light commercial vehicles electric | D20: ELEC | E20: all | F20: 4.5 | G20: gompertz | H20: 1.798 | I20: -0.137 | J20: =IF(D20="D", 250, 50) -> 50 | K20: Light Commercial Vehicles | L20: =IF(D20="G","Petrol",IF(D20="D","Diesel",IF(D20="HY","Petrol Hybrid",IF(D20="GLP","LPG Bifuell ~ LPG",D20)))) -> ELEC | M20: N1-I | Q20: 34.2 | R20: FTP-75 | S20: 17.787 | U20: LCV | V20: 4S | W20: <3.5 | X20: =D20 -> ELEC
A21: LCV | B21: LCV_HY | C21: Light commercial vehicles electric | D21: HY | E21: all | F21: 4.5 | G21: gompertz | H21: 1.798 | I21: -0.137 | J21: =IF(D21="D", 250, 50) -> 50 | K21: Light Commercial Vehicles | L21: =IF(D21="G","Petrol",IF(D21="D","Diesel",IF(D21="HY","Petrol Hybrid",IF(D21="GLP","LPG Bifuell ~ LPG",D21)))) -> Petrol Hybrid | M21: N1-I | Q21: 34.2 | R21: FTP-75 | S21: 17.787 | U21: PC | V21: 4S | W21: 1400_2000 | X21: FH
A22: TRUCKS | B22: TRUCKS_RT_7_D | C22: =CONCATENATE("Rigid trucks diesel ", E22) -> Rigid trucks diesel <=7.5t | D22: D | E22: <=7.5t | G22: double_logistic | H22: 0.1 | I22: 17 | J22: =IF(D22="D", 250, 50) -> 250 | K22: Heavy Duty Trucks | L22: =IF(D22="G","Petrol",IF(D22="D","Diesel",IF(D22="HY","Petrol Hybrid",IF(D22="GLP","LPG Bifuell ~ LPG",D22)))) -> Diesel | M22: Rigid <=7,5 t | O22: 0 | P22: 0.5 | Q22: 22.8 | R22: City Suburban cycle | S22: 10.752 | U22: Trucks | V22: RT | W22: <=7.5 | X22: =D22 -> D
A23: TRUCKS | B23: TRUCKS_RT_7_12_D | C23: =CONCATENATE("Rigid trucks diesel ", E23) -> Rigid trucks diesel 7.5-12t | D23: D | E23: 7.5-12t | G23: double_logistic | H23: 0.1 | I23: 17 | J23: =IF(D23="D", 250, 50) -> 250 | K23: Heavy Duty Trucks | L23: =IF(D23="G","Petrol",IF(D23="D","Diesel",IF(D23="HY","Petrol Hybrid",IF(D23="GLP","LPG Bifuell ~ LPG",D23)))) -> Diesel | M23: Rigid 7,5 - 12 t | O23: 0 | P23: 0.5 | Q23: 22.8 | R23: City Suburban cycle | S23: 10.752 | U23: Trucks | V23: RT | W23: >7.5 & <=12 | X23: =D23 -> D
A24: TRUCKS | B24: TRUCKS_RT_12_14_D | C24: =CONCATENATE("Rigid trucks diesel ", E24) -> Rigid trucks diesel 12-14t | D24: D | E24: 12-14t | G24: double_logistic | H24: 0.1 | I24: 17 | J24: =IF(D24="D", 250, 50) -> 250 | K24: Heavy Duty Trucks | L24: =IF(D24="G","Petrol",IF(D24="D","Diesel",IF(D24="HY","Petrol Hybrid",IF(D24="GLP","LPG Bifuell ~ LPG",D24)))) -> Diesel | M24: Rigid 12 - 14 t | O24: 0 | P24: 0.5 | Q24: 22.8 | R24: City Suburban cycle | S24: 10.752 | U24: Trucks | V24: RT | W24: >12 & <=14 | X24: =D24 -> D
A25: TRUCKS | B25: TRUCKS_RT_14_16_D | C25: =CONCATENATE("Rigid trucks diesel ", E25) -> Rigid trucks diesel 14-16t | D25: D | E25: 14-16t | G25: double_logistic | H25: 0.1 | I25: 17 | J25: =IF(D25="D", 250, 50) -> 250 | K25: Heavy Duty Trucks | L25: =IF(D25="G","Petrol",IF(D25="D","Diesel",IF(D25="HY","Petrol Hybrid",IF(D25="GLP","LPG Bifuell ~ LPG",D25)))) -> Diesel | M25: Rigid 14 - 20 t | O25: 0 | P25: 0.5 | Q25: 22.8 | R25: City Suburban cycle | S25: 10.752 | U25: Trucks | V25: RT | W25: >14 & <=20 | X25: =D25 -> D
A26: TRUCKS | B26: TRUCKS_RT_16_20_D | C26: =CONCATENATE("Rigid trucks diesel ", E26) -> Rigid trucks diesel 16-20t | D26: D | E26: 16-20t | G26: double_logistic | H26: 0.1 | I26: 17 | J26: =IF(D26="D", 250, 50) -> 250 | K26: Heavy Duty Trucks | L26: =IF(D26="G","Petrol",IF(D26="D","Diesel",IF(D26="HY","Petrol Hybrid",IF(D26="GLP","LPG Bifuell ~ LPG",D26)))) -> Diesel | M26: Rigid 14 - 20 t | O26: 0 | P26: 0.5 | Q26: 22.8 | R26: City Suburban cycle | S26: 10.752 | U26: Trucks | V26: RT | W26: >14 & <=20 | X26: =D26 -> D
A27: TRUCKS | B27: TRUCKS_RT_20_26_D | C27: =CONCATENATE("Rigid trucks diesel ", E27) -> Rigid trucks diesel 20-26t | D27: D | E27: 20-26t | G27: double_logistic | H27: 0.1 | I27: 17 | J27: =IF(D27="D", 250, 50) -> 250 | K27: Heavy Duty Trucks | L27: =IF(D27="G","Petrol",IF(D27="D","Diesel",IF(D27="HY","Petrol Hybrid",IF(D27="GLP","LPG Bifuell ~ LPG",D27)))) -> Diesel | M27: Rigid 20 - 26 t | O27: 0 | P27: 0.5 | Q27: 22.8 | R27: City Suburban cycle | S27: 10.752 | U27: Trucks | V27: RT | W27: >20 & <=26 | X27: =D27 -> D
A28: TRUCKS | B28: TRUCKS_RT_26_28_D | C28: =CONCATENATE("Rigid trucks diesel ", E28) -> Rigid trucks diesel 26-28t | D28: D | E28: 26-28t | G28: double_logistic | H28: 0.1 | I28: 17 | J28: =IF(D28="D", 250, 50) -> 250 | K28: Heavy Duty Trucks | L28: =IF(D28="G","Petrol",IF(D28="D","Diesel",IF(D28="HY","Petrol Hybrid",IF(D28="GLP","LPG Bifuell ~ LPG",D28)))) -> Diesel | M28: Rigid 26 - 28 t | O28: 0 | P28: 0.5 | Q28: 22.8 | R28: City Suburban cycle | S28: 10.752 | U28: Trucks | V28: RT | W28: >26 & <=28 | X28: =D28 -> D
A29: TRUCKS | B29: TRUCKS_RT_28_32_D | C29: =CONCATENATE("Rigid trucks diesel ", E29) -> Rigid trucks diesel 38-32t | D29: D | E29: 38-32t | G29: double_logistic | H29: 0.1 | I29: 17 | J29: =IF(D29="D", 250, 50) -> 250 | K29: Heavy Duty Trucks | L29: =IF(D29="G","Petrol",IF(D29="D","Diesel",IF(D29="HY","Petrol Hybrid",IF(D29="GLP","LPG Bifuell ~ LPG",D29)))) -> Diesel | M29: Rigid 28 - 32 t | O29: 0 | P29: 0.5 | Q29: 22.8 | R29: City Suburban cycle | S29: 10.752 | U29: Trucks | V29: RT | W29: >28 & <=32 | X29: =D29 -> D
A30: TRUCKS | B30: TRUCKS_RT_32_D | C30: =CONCATENATE("Rigid trucks diesel ", E30) -> Rigid trucks diesel >=32t | D30: D | E30: >=32t | G30: double_logistic | H30: 0.1 | I30: 17 | J30: =IF(D30="D", 250, 50) -> 250 | K30: Heavy Duty Trucks | L30: =IF(D30="G","Petrol",IF(D30="D","Diesel",IF(D30="HY","Petrol Hybrid",IF(D30="GLP","LPG Bifuell ~ LPG",D30)))) -> Diesel | M30: Rigid >32 t | O30: 0 | P30: 0.5 | Q30: 22.8 | R30: City Suburban cycle | S30: 10.752 | U30: Trucks | V30: RT | W30: >32 | X30: =D30 -> D
A31: TRUCKS | B31: TRUCKS_RT_7_G | C31: =CONCATENATE("Rigid trucks gasoline ", E31) -> Rigid trucks gasoline <=7.5t | D31: G | E31: <=7.5t | G31: double_logistic | H31: 0.1 | I31: 17 | J31: =IF(D31="D", 250, 50) -> 50 | K31: Passenger Cars | L31: =IF(D31="G","Petrol",IF(D31="D","Diesel",IF(D31="HY","Petrol Hybrid",IF(D31="GLP","LPG Bifuell ~ LPG",D31)))) -> Petrol | M31: Large-SUV-Executive | Q31: 22.8 | R31: City Suburban cycle | S31: 10.752 | T31: tratados como PC para incorporar euro. Camiones gasolineros solo tienen pre-euro | U31: PC | V31: 4S | W31: >2000 | X31: =D31 -> G
A32: TRUCKS | B32: TRUCKS_RT_7_12_G | C32: =CONCATENATE("Rigid trucks gasoline ", E32) -> Rigid trucks gasoline 7.5-12t | D32: G | E32: 7.5-12t | G32: double_logistic | H32: 0.1 | I32: 17 | J32: =IF(D32="D", 250, 50) -> 50 | K32: Passenger Cars | L32: =IF(D32="G","Petrol",IF(D32="D","Diesel",IF(D32="HY","Petrol Hybrid",IF(D32="GLP","LPG Bifuell ~ LPG",D32)))) -> Petrol | M32: Large-SUV-Executive | Q32: 22.8 | R32: City Suburban cycle | S32: 10.752 | U32: PC | V32: 4S | W32: >2000 | X32: =D32 -> G
A33: TRUCKS | B33: TRUCKS_RT_12_14_G | C33: =CONCATENATE("Rigid trucks gasoline ", E33) -> Rigid trucks gasoline 12-14t | D33: G | E33: 12-14t | G33: double_logistic | H33: 0.1 | I33: 17 | J33: =IF(D33="D", 250, 50) -> 50 | K33: Passenger Cars | L33: =IF(D33="G","Petrol",IF(D33="D","Diesel",IF(D33="HY","Petrol Hybrid",IF(D33="GLP","LPG Bifuell ~ LPG",D33)))) -> Petrol | M33: Large-SUV-Executive | Q33: 22.8 | R33: City Suburban cycle | S33: 10.752 | U33: PC | V33: 4S | W33: >2000 | X33: =D33 -> G
A34: TRUCKS | B34: TRUCKS_RT_14_16_G | C34: =CONCATENATE("Rigid trucks gasoline ", E34) -> Rigid trucks gasoline 14-16t | D34: G | E34: 14-16t | G34: double_logistic | H34: 0.1 | I34: 17 | J34: =IF(D34="D", 250, 50) -> 50 | K34: Passenger Cars | L34: =IF(D34="G","Petrol",IF(D34="D","Diesel",IF(D34="HY","Petrol Hybrid",IF(D34="GLP","LPG Bifuell ~ LPG",D34)))) -> Petrol | M34: Large-SUV-Executive | Q34: 22.8 | R34: City Suburban cycle | S34: 10.752 | U34: PC | V34: 4S | W34: >2000 | X34: =D34 -> G
A35: TRUCKS | B35: TRUCKS_RT_16_20_G | C35: =CONCATENATE("Rigid trucks gasoline ", E35) -> Rigid trucks gasoline 16-20t | D35: G | E35: 16-20t | G35: double_logistic | H35: 0.1 | I35: 17 | J35: =IF(D35="D", 250, 50) -> 50 | K35: Passenger Cars | L35: =IF(D35="G","Petrol",IF(D35="D","Diesel",IF(D35="HY","Petrol Hybrid",IF(D35="GLP","LPG Bifuell ~ LPG",D35)))) -> Petrol | M35: Large-SUV-Executive | Q35: 22.8 | R35: City Suburban cycle | S35: 10.752 | U35: PC | V35: 4S | W35: >2000 | X35: =D35 -> G
A36: TRUCKS | B36: TRUCKS_RT_20_26_G | C36: =CONCATENATE("Rigid trucks gasoline ", E36) -> Rigid trucks gasoline 20-26t | D36: G | E36: 20-26t | G36: double_logistic | H36: 0.1 | I36: 17 | J36: =IF(D36="D", 250, 50) -> 50 | K36: Passenger Cars | L36: =IF(D36="G","Petrol",IF(D36="D","Diesel",IF(D36="HY","Petrol Hybrid",IF(D36="GLP","LPG Bifuell ~ LPG",D36)))) -> Petrol | M36: Large-SUV-Executive | Q36: 22.8 | R36: City Suburban cycle | S36: 10.752 | U36: PC | V36: 4S | W36: >2000 | X36: =D36 -> G
A37: TRUCKS | B37: TRUCKS_RT_26_28_G | C37: =CONCATENATE("Rigid trucks gasoline ", E37) -> Rigid trucks gasoline 26-28t | D37: G | E37: 26-28t | G37: double_logistic | H37: 0.1 | I37: 17 | J37: =IF(D37="D", 250, 50) -> 50 | K37: Passenger Cars | L37: =IF(D37="G","Petrol",IF(D37="D","Diesel",IF(D37="HY","Petrol Hybrid",IF(D37="GLP","LPG Bifuell ~ LPG",D37)))) -> Petrol | M37: Large-SUV-Executive | Q37: 22.8 | R37: City Suburban cycle | S37: 10.752 | U37: PC | V37: 4S | W37: >2000 | X37: =D37 -> G
A38: TRUCKS | B38: TRUCKS_RT_28_32_G | C38: =CONCATENATE("Rigid trucks gasoline ", E38) -> Rigid trucks gasoline 38-32t | D38: G | E38: 38-32t | G38: double_logistic | H38: 0.1 | I38: 17 | J38: =IF(D38="D", 250, 50) -> 50 | K38: Passenger Cars | L38: =IF(D38="G","Petrol",IF(D38="D","Diesel",IF(D38="HY","Petrol Hybrid",IF(D38="GLP","LPG Bifuell ~ LPG",D38)))) -> Petrol | M38: Large-SUV-Executive | Q38: 22.8 | R38: City Suburban cycle | S38: 10.752 | U38: PC | V38: 4S | W38: >2000 | X38: =D38 -> G
A39: TRUCKS | B39: TRUCKS_RT_32_G | C39: =CONCATENATE("Rigid trucks gasoline ", E39) -> Rigid trucks gasoline >=32t | D39: G | E39: >=32t | G39: double_logistic | H39: 0.1 | I39: 17 | J39: =IF(D39="D", 250, 50) -> 50 | K39: Passenger Cars | L39: =IF(D39="G","Petrol",IF(D39="D","Diesel",IF(D39="HY","Petrol Hybrid",IF(D39="GLP","LPG Bifuell ~ LPG",D39)))) -> Petrol | M39: Large-SUV-Executive | Q39: 22.8 | R39: City Suburban cycle | S39: 10.752 | U39: PC | V39: 4S | W39: >2000 | X39: =D39 -> G
A40: TRUCKS | B40: TRUCKS_AT_16_20_D | C40: =CONCATENATE("Articulated trucks diesel ", E40) -> Articulated trucks diesel 16-20t | D40: D | E40: 16-20t | G40: double_logistic | H40: 0.1 | I40: 17 | J40: =IF(D40="D", 250, 50) -> 250 | K40: Heavy Duty Trucks | L40: =IF(D40="G","Petrol",IF(D40="D","Diesel",IF(D40="HY","Petrol Hybrid",IF(D40="GLP","LPG Bifuell ~ LPG",D40)))) -> Diesel | M40: Articulated 14 - 20 t | O40: 0 | P40: 0.5 | Q40: 22.8 | R40: City Suburban cycle | S40: 10.752 | U40: Trucks | V40: TT | W40: >20 & <=28 | X40: =D40 -> D
...

Sheet fleet_age
A1: Year | B1: PC_MINI_G | C1: PC_SMALL_G | D1: PC_MEDIUM_G | E1: PC_SUV_G | F1: PC_MINI_D | G1: PC_SMALL_D | H1: PC_MEDIUM_D | I1: PC_SUV_D | J1: PC_ELEC | K1: PC_SMALL_HY | L1: TAXI_SMALL_G | M1: TAXI_SMALL_GLP | N1: LCV_NI_G | O1: LCV_NII_G | P1: LCV_NIII_G | Q1: LCV_NI_D | R1: LCV_NII_D | S1: LCV_NIII_D | T1: LCV_ELEC | U1: LCV_HY | V1: TRUCKS_RT_7_D | W1: TRUCKS_RT_7_12_D | X1: TRUCKS_RT_12_14_D | Y1: TRUCKS_RT_14_16_D | Z1: TRUCKS_RT_16_20_D | AA1: TRUCKS_RT_20_26_D | AB1: TRUCKS_RT_26_28_D | AC1: TRUCKS_RT_28_32_D | AD1: TRUCKS_RT_32_D | AE1: TRUCKS_RT_7_G | AF1: TRUCKS_RT_7_12_G | AG1: TRUCKS_RT_12_14_G | AH1: TRUCKS_RT_14_16_G | AI1: TRUCKS_RT_16_20_G | AJ1: TRUCKS_RT_20_26_G | AK1: TRUCKS_RT_26_28_G | AL1: TRUCKS_RT_28_32_G | AM1: TRUCKS_RT_32_G | AN1: TRUCKS_AT_16_20_D | AO1: TRUCKS_AT_20_28_D | AP1: TRUCKS_AT_28_34_D | AQ1: TRUCKS_AT_34_40_D | AR1: TRUCKS_AT_40_50_D | AS1: TRUCKS_AT_50_60_D | AT1: TRUCKS_ELEC | AU1: BUS_UB_15_D | AV1: BUS_UB_15_18_D | AW1: BUS_UB_18_D | AX1: BUS_UB_15_G | AY1: BUS_UB_15_18_G | AZ1: BUS_UB_18_G | BA1: BUS_COACH_17_D | BB1: BUS_COACH_18_D | BC1: BUS_COACH_17_G | BD1: BUS_COACH_18_G | BE1: BUS_UB_15_HY | BF1: BUS_ELEC | BG1: MC_2S_50_G | BH1: MC_4S_50_250_G | BI1: MC_4S_250_750_G | BJ1: MC_4S_750_G | BK1: MC_ELEC | BL1: Region
A2: 2026 | B2: 0 | C2: 0 | D2: 0 | E2: 0 | F2: 0 | G2: 0 | H2: 0 | I2: 0 | J2: 0 | K2: 0 | L2: 0 | M2: 0 | N2: 0 | O2: 0 | P2: 0 | Q2: 0 | R2: 0 | S2: 0 | T2: 0 | U2: 0 | V2: 0 | W2: 0 | X2: 0 | Y2: 0 | Z2: 0 | AA2: 0 | AB2: 0 | AC2: 0 | AD2: 0 | AE2: 0 | AF2: 0 | AG2: 0 | AH2: 0 | AI2: 0 | AJ2: 0 | AK2: 0 | AL2: 0 | AM2: 0 | AN2: 0 | AO2: 0 | AP2: 0 | AQ2: 0 | AR2: 0 | AS2: 0 | AT2: 0 | AU2: 0 | AV2: 0 | AW2: 0 | AX2: 0 | AY2: 0 | AZ2: 0 | BA2: 0 | BB2: 0 | BC2: 0 | BD2: 0 | BE2: 0 | BF2: 0 | BG2: 0.15734693 | BH2: 26.592981 | BI2: 0.22778869 | BJ2: 0.00296881 | BK2: 0.0080967545 | BL2: EC
A3: 2025 | B3: 153.02269 | C3: 4820.2146 | D3: 2677.897 | E3: 17070.015 | F3: 1.0821987 | G3: 34.089258 | H3: 18.938476 | I3: 120.72162 | J3: 5.026721 | K3: 83.650287 | L3: 245.44069 | M3: 0.21506944 | N3: 1073.1759 | O3: 98.682844 | P3: 61.676777 | Q3: 1033.3332 | R3: 406.02968 | S3: 131.86612 | T3: 0.021478315 | U3: 0.0070199318 | V3: 1733.2907 | W3: 681.06535 | X3: 221.18935 | Y3: 221.18935 | Z3: 144.58622 | AA3: 144.58622 | AB3: 144.58622 | AC3: 144.58622 | AD3: 144.58622 | AE3: 6.6374673 | AF3: 2.6080732 | AG3: 0.847023 | AH3: 0.847023 | AI3: 0.55367879 | AJ3: 0.55367879 | AK3: 0.55367879 | AL3: 0.55367879 | AM3: 0.55367879 | AN3: 1.1949731 | AO3: 19.453051 | AP3: 21.509516 | AQ3: 78.515432 | AR3: 78.515432 | AS3: 78.515432 | AT3: 0.0002188176 | AU3: 56.413013 | AV3: 62.221217 | AW3: 4.1391797 | AX3: 0.19587852 | AY3: 0.21604589 | AZ3: 0.014372152 | BA3: 27.861575 | BB3: 71.901557 | BC3: 0.09674158 | BD3: 0.24965818 | BE3: 0.19587852 | BF3: 0.0019587852 | BG3: 471.03843 | BH3: 79609.535 | BI3: 681.91498 | BJ3: 8.8875176 | BK3: 24.238684 | BL3: EC
A4: 2024 | B4: 537.38322 | C4: 16927.571 | D4: 9404.2064 | E4: 52188.01 | F4: 3.8004522 | G4: 119.71424 | H4: 66.507913 | I4: 369.08118 | J4: 17.652778 | K4: 293.76207 | L4: 861.93565 | M4: 0.51792232 | N4: 2584.3828 | O4: 237.6444 | P4: 148.52775 | Q4: 2107.7791 | R4: 805.86754 | S4: 252.68 | T4: 0.041156446 | U4: 0.012180902 | V4: 3535.5427 | W4: 1351.7447 | X4: 423.83994 | Y4: 423.83994 | Z4: 250.88429 | AA4: 250.88429 | AB4: 250.88429 | AC4: 250.88429 | AD4: 250.88429 | AE4: 13.539015 | AF4: 5.1763741 | AG4: 1.6230536 | AH4: 1.6230536 | AI4: 0.96073686 | AJ4: 0.96073686 | AK4: 0.96073686 | AL4: 0.96073686 | AM4: 0.96073686 | AN4: 3.8932995 | AO4: 63.379294 | AP4: 70.079391 | AQ4: 255.80834 | AR4: 255.80834 | AS4: 255.80834 | AT4: 0.00044634116 | AU4: 177.68857 | AV4: 195.98313 | AW4: 13.037504 | AX4: 0.61697419 | AY4: 0.68049698 | AZ4: 0.045269112 | BA4: 87.757825 | BB4: 226.47407 | BC4: 0.30471467 | BD4: 0.78636829 | BE4: 0.61697419 | BF4: 0.0061697419 | BG4: 797.32934 | BH4: 134755.5 | BI4: 1154.2812 | BJ4: 15.04395 | BK4: 41.028954 | BL4: EC
A5: 2023 | B5: 536.23268 | C5: 16891.329 | D5: 9384.0718 | E5: 56070.616 | F5: 3.7923153 | G5: 119.45793 | H5: 66.365519 | I5: 396.53954 | J5: 17.614983 | K5: 293.13312 | L5: 860.09024 | M5: 0.38313226 | N5: 1911.7933 | O5: 175.79709 | P5: 109.87318 | Q5: 2548.6759 | R5: 972.33124 | S5: 304.30424 | T5: 0.049564987 | U5: 0.013920418 | V5: 4275.0935 | W5: 1630.9673 | X5: 510.43331 | Y5: 510.43331 | Z5: 286.71227 | AA5: 286.71227 | AB5: 286.71227 | AC5: 286.71227 | AD5: 286.71227 | AE5: 16.371053 | AF5: 6.2456297 | AG5: 1.9546544 | AH5: 1.9546544 | AI5: 1.0979366 | AJ5: 1.0979366 | AK5: 1.0979366 | AL5: 1.0979366 | AM5: 1.0979366 | AN5: 5.7821279 | AO5: 94.127664 | AP5: 104.0783 | AQ5: 379.91338 | AR5: 379.91338 | AS5: 379.91338 | AT5: 0.00053970503 | AU5: 151.09741 | AV5: 166.65419 | AW5: 11.086437 | AX5: 0.52464379 | AY5: 0.57866037 | AZ5: 0.038494574 | BA5: 74.624836 | BB5: 192.58214 | BC5: 0.25911401 | BD5: 0.668688 | BE5: 0.52464379 | BF5: 0.0052464379 | BG5: 575.45852 | BH5: 97257.424 | BI5: 833.08231 | BJ5: 10.857708 | BK5: 29.61193 | BL5: EC
A6: 2022 | B6: 473.86915 | C6: 14926.878 | D6: 8292.7102 | E6: 39429.619 | F6: 3.3512715 | G6: 105.56505 | H6: 58.647251 | I6: 278.85199 | J6: 15.566372 | K6: 259.04192 | L6: 760.06229 | M6: 0.22016654 | N6: 1098.61 | O6: 101.02161 | P6: 63.138505 | Q6: 2410.6848 | R6: 908.60895 | S6: 279.85111 | T6: 0.045582068 | U6: 0.011902171 | V6: 4043.6302 | W6: 1524.0809 | X6: 469.41616 | Y6: 469.41616 | Z6: 245.1434 | AA6: 245.1434 | AB6: 245.1434 | AC6: 245.1434 | AD6: 245.1434 | AE6: 15.484687 | AF6: 5.8363187 | AG6: 1.7975833 | AH6: 1.7975833 | AI6: 0.93875268 | AJ6: 0.93875268 | AK6: 0.93875268 | AL6: 0.93875268 | AM6: 0.93875268 | AN6: 3.5378057 | AO6: 57.592186 | AP6: 63.680502 | AQ6: 232.45071 | AR6: 232.45071 | AS6: 232.45071 | AT6: 0.00051048417 | AU6: 42.744662 | AV6: 47.145592 | AW6: 3.1362947 | AX6: 0.14841897 | AY6: 0.16369997 | AZ6: 0.010889912 | BA6: 21.110973 | BB6: 54.480475 | BC6: 0.07330199 | BD6: 0.18916832 | BE6: 0.14841897 | BF6: 0.0014841897 | BG6: 542.02521 | BH6: 91606.909 | BI6: 784.68143 | BJ6: 10.226891 | BK6: 27.89152 | BL6: EC
A7: 2021 | B7: 285.35503 | C7: 8988.6836 | D7: 4993.7131 | E7: 18133.783 | F7: 2.0180722 | G7: 63.569276 | H7: 35.316264 | I7: 128.24475 | J7: 9.3737745 | K7: 155.99014 | L7: 457.69512 | M7: 0.15871813 | N7: 791.98829 | O7: 72.826509 | P7: 45.516568 | Q7: 1637.441 | R7: 609.88192 | S7: 184.82906 | T7: 0.030104904 | U7: 0.0072774567 | V7: 2746.608 | W7: 1023.0027 | X7: 310.02824 | Y7: 310.02824 | Z7: 149.89034 | AA7: 149.89034 | AB7: 149.89034 | AC7: 149.89034 | AD7: 149.89034 | AE7: 10.517867 | AF7: 3.9174887 | AG7: 1.1872228 | AH7: 1.1872228 | AI7: 0.57399039 | AJ7: 0.57399039 | AK7: 0.57399039 | AL7: 0.57399039 | AM7: 0.57399039 | AN7: 1.7988843 | AO7: 29.284162 | AP7: 32.379917 | AQ7: 118.19527 | AR7: 118.19527 | AS7: 118.19527 | AT7: 0.00034674286 | AU7: 100.89728 | AV7: 111.28553 | AW7: 7.4031143 | AX7: 0.35033779 | AY7: 0.38640807 | AZ7: 0.025705258 | BA7: 49.831716 | BB7: 128.59926 | BC7: 0.17302679 | BD7: 0.44652521 | BE7: 0.35033779 | BF7: 0.0035033779 | BG7: 425.99059 | BH7: 71996.063 | BI7: 616.69992 | BJ7: 8.0375583 | BK7: 21.920613 | BL7: EC
A8: 2020 | B8: 726.93088 | C8: 22898.323 | D8: 12721.29 | E8: 29570.995 | F8: 5.1409608 | G8: 161.94026 | H8: 89.966813 | I8: 209.13037 | J8: 23.879327 | K8: 397.37884 | L8: 1165.9606 | M8: 0.3334355 | N8: 1663.8113 | O8: 152.99414 | P8: 95.621337 | Q8: 1848.291 | R8: 689.83681 | S8: 209.58498 | T8: 0.034137141 | U8: 0.0085121119 | V8: 3100.2831 | W8: 1157.1173 | X8: 351.55328 | Y8: 351.55328 | Z8: 175.31995 | AA8: 175.31995 | AB8: 175.31995 | AC8: 175.31995 | AD8: 175.31995 | AE8: 11.872231 | AF8: 4.4310674 | AG8: 1.3462389 | AH8: 1.3462389 | AI8: 0.67137059 | AJ8: 0.67137059 | AK8: 0.67137059 | AL8: 0.67137059 | AM8: 0.67137059 | AN8: 4.3644358 | AO8: 71.048955 | AP8: 78.559845 | AQ8: 286.76425 | AR8: 286.76425 | AS8: 286.76425 | AT8: 0.00039139223 | AU8: 343.69691 | AV8: 379.08345 | AW8: 25.217998 | AX8: 1.193392 | AY8: 1.316262 | AZ8: 0.087562492 | BA8: 169.74695 | BB8: 438.06103 | BC8: 0.58939914 | BD8: 1.5210452 | BE8: 1.193392 | BF8: 0.01193392 | BG8: 386.89279 | BH8: 65388.2 | BI8: 560.09865 | BJ8: 7.2998639 | BK8: 19.90872 | BL8: EC
A9: 2019 | B9: 1197.7774 | C9: 37729.989 | D9: 20961.105 | E9: 41756.063 | F9: 8.4708558 | G9: 266.83196 | H9: 148.23998 | I9: 295.30494 | J9: 39.346407 | K9: 654.76844 | L9: 1921.1747 | M9: 0.61108604 | N9: 3049.2609 | O9: 280.39181 | P9: 175.24488 | Q9: 1851.9599 | R9: 707.0356 | S9: 221.50145 | T9: 0.036078093 | U9: 0.010133562 | V9: 3106.4373 | W9: 1185.9661 | X9: 371.54171 | Y9: 371.54171 | Z9: 208.71619 | AA9: 208.71619 | AB9: 208.71619 | AC9: 208.71619 | AD9: 208.71619 | AE9: 11.895798 | AF9: 4.5415414 | AG9: 1.4227827 | AH9: 1.4227827 | AI9: 0.79925825 | AJ9: 0.79925825 | AK9: 0.79925825 | AL9: 0.79925825 | AM9: 0.79925825 | AN9: 3.7262602 | AO9: 60.66005 | AP9: 67.072684 | AQ9: 244.83307 | AR9: 244.83307 | AS9: 244.83307 | AT9: 0.00039216916 | AU9: 469.19722 | AV9: 517.5051 | AW9: 34.426305 | AX9: 1.629157 | AY9: 1.7968927 | AZ9: 0.11953578 | BA9: 231.72975 | BB9: 598.01823 | BC9: 0.8046172 | BD9: 2.0764522 | BE9: 1.629157 | BF9: 0.01629157 | BG9: 321.54136 | BH9: 54343.248 | BI9: 465.49041 | BJ9: 6.0668182 | BK9: 16.545868 | BL9: EC
A10: 2018 | B10: 777.06741 | C10: 24477.623 | D10: 13598.68 | E10: 27488.311 | F10: 5.4955336 | G10: 173.10931 | H10: 96.171837 | I10: 194.40133 | J10: 25.526288 | K10: 424.78612 | L10: 1246.377 | M10: 0.2513155 | N10: 1254.0403 | O10: 115.31405 | P10: 72.071283 | Q10: 1366.3423 | R10: 518.41614 | S10: 161.10965 | T10: 0.026241493 | U10: 0.0070886619 | V10: 2291.8728 | W10: 869.57995 | X10: 270.24182 | Y10: 270.24182 | Z10: 146.00182 | AA10: 146.00182 | AB10: 146.00182 | AC10: 146.00182 | AD10: 146.00182 | AE10: 8.776503 | AF10: 3.3299714 | AG10: 1.0348646 | AH10: 1.0348646 | AI10: 0.55909969 | AJ10: 0.55909969 | AK10: 0.55909969 | AL10: 0.55909969 | AM10: 0.55909969 | AN10: 1.5847314 | AO10: 25.797952 | AP10: 28.525165 | AQ10: 104.12441 | AR10: 104.12441 | AS10: 104.12441 | AT10: 0.00028933526 | AU10: 456.27442 | AV10: 503.25178 | AW10: 33.478123 | AX10: 1.5842862 | AY10: 1.747402 | AZ10: 0.11624348 | BA10: 225.34737 | BB10: 581.54739 | BC10: 0.78245613 | BD10: 2.0192618 | BE10: 1.5842862 | BF10: 0.015842862 | BG10: 307.29273 | BH10: 51935.106 | BI10: 444.86288 | BJ10: 5.797976 | BK10: 15.812662 | BL10: EC
A11: 2017 | B11: 479.52438 | C11: 15105.018 | D11: 8391.6767 | E11: 16290.959 | F11: 3.3912661 | G11: 106.82488 | H11: 59.347156 | I11: 115.21202 | J11: 15.752143 | K11: 262.13337 | L11: 769.13299 | M11: 0.17046978 | N11: 850.62792 | O11: 78.218659 | P11: 48.886662 | Q11: 486.5305 | R11: 185.30993 | S11: 57.92656 | T11: 0.0094350614 | U11: 0.0025132049 | V11: 816.09567 | W11: 310.83485 | X11: 97.164751 | Y11: 97.164751 | Z11: 51.763293 | AA11: 51.763293 | AB11: 51.763293 | AC11: 51.763293 | AD11: 51.763293 | AE11: 3.1251586 | AF11: 1.1903117 | AG11: 0.37208291 | AH11: 0.37208291 | AI11: 0.19822247 | AJ11: 0.19822247 | AK11: 0.19822247 | AL11: 0.19822247 | AM11: 0.19822247 | AN11: 0.081378097 | AO11: 1.3247597 | AP11: 1.4648057 | AQ11: 5.3469291 | AR11: 5.3469291 | AS11: 5.3469291 | AT11: 0.00010302721 | AU11: 306.91662 | AV11: 338.51631 | AW11: 22.519326 | AX11: 1.0656827 | AY11: 1.1754039 | AZ11: 0.078192103 | BA11: 151.5817 | BB11: 391.18248 | BC11: 0.52632534 | BD11: 1.3582725 | BE11: 1.0656827 | BF11: 0.010656827 | BG11: 165.03362 | BH11: 27892.097 | BI11: 238.91659 | BJ11: 3.1138419 | BK11: 8.492296 | BL11: EC
A12: 2016 | B12: 381.25991 | C12: 12009.687 | D12: 6672.0484 | E12: 13641.776 | F12: 2.6963255 | G12: 84.934252 | H12: 47.185695 | I12: 96.476624 | J12: 12.524203 | K12: 208.41682 | L12: 611.52172 | M12: 0.34051481 | N12: 1699.1363 | O12: 156.24242 | P12: 97.651514 | Q12: 1453.8493 | R12: 551.3448 | S12: 171.24342 | T12: 0.027892079 | U12: 0.0074870442 | V12: 2438.6553 | W12: 924.81376 | X12: 287.23998 | Y12: 287.23998 | Z12: 154.20711 | AA12: 154.20711 | AB12: 154.20711 | AC12: 154.20711 | AD12: 154.20711 | AE12: 9.3385919 | AF12: 3.5414839 | AG12: 1.0999574 | AH12: 1.0999574 | AI12: 0.59052106 | AJ12: 0.59052106 | AK12: 0.59052106 | AL12: 0.59052106 | AM12: 0.59052106 | AN12: 1.3919938 | AO12: 22.660364 | AP12: 25.055888 | AQ12: 91.460629 | AR12: 91.460629 | AS12: 91.460629 | AT12: 0.00030786567 | AU12: 414.02679 | AV12: 456.6544 | AW12: 30.378297 | AX12: 1.437593 | AY12: 1.5856055 | AZ12: 0.1054802 | BA12: 204.48187 | BB12: 527.70041 | BC12: 0.71000649 | BD12: 1.8322931 | BE12: 1.437593 | BF12: 0.01437593 | BG12: 106.05766 | BH12: 17924.654 | BI12: 153.53802 | BJ12: 2.0010879 | BK12: 5.4575124 | BL12: EC
A13: 2015 | B13: 707.39109 | C13: 22282.819 | D13: 12379.344 | E13: 25691.313 | F13: 5.0027725 | G13: 157.58733 | H13: 87.548519 | I13: 181.6927 | J13: 23.237454 | K13: 386.69736 | L13: 1134.6197 | M13: 0.54284149 | N13: 2708.7271 | O13: 249.07836 | P13: 155.67397 | Q13: 3006.8076 | R13: 1163.4883 | S13: 370.83174 | T13: 0.060400967 | U13: 0.018223972 | V13: 5043.5536 | W13: 1951.6099 | X13: 622.02509 | Y13: 622.02509 | Z13: 375.35055 | AA13: 375.35055 | AB13: 375.35055 | AC13: 375.35055 | AD13: 375.35055 | AE13: 19.313796 | AF13: 7.4734994 | AG13: 2.3819843 | AH13: 2.3819843 | AI13: 1.4373682 | AJ13: 1.4373682 | AK13: 1.4373682 | AL13: 1.4373682 | AM13: 1.4373682 | AN13: 5.863506 | AO13: 95.452424 | AP13: 105.54311 | AQ13: 385.26031 | AR13: 385.26031 | AS13: 385.26031 | AT13: 0.00063671854 | AU13: 377.74353 | AV13: 416.63546 | AW13: 27.716093 | AX13: 1.3116095 | AY13: 1.4466509 | AZ13: 0.096236434 | BA13: 186.56209 | BB13: 481.45536 | BC13: 0.64778503 | BD13: 1.67172 | BE13: 1.3116095 | BF13: 0.013116095 | BG13: 234.92479 | BH13: 39704.305 | BI13: 340.09696 | BJ13: 4.4325433 | BK13: 12.088754 | BL13: EC
... A68: 1960 | B68: 0.7664258 | C68: 24.142413 | D68: 13.412452 | E68: 17.004837 | F68: 0.0054202746 | G68: 0.17073865 | H68: 0.094854805 | I68: 0.12026068 | J68: 0.025176716 | K68: 0.41896885 | L68: 1.2293084 | M68: 0.00029485027 | N68: 1.4712747 | O68: 0.13528962 | P68: 0.084556014 | Q68: 2.3759937 | R68: 0.9484651 | S68: 0.31391977 | T68: 5.1131163e-05 | U68: 1.7813954e-05 | V68: 3.9854402 | W68: 1.5909347 | X68: 0.5265622 | Y68: 0.5265622 | Z68: 0.36690559 | AA68: 0.36690559 | AB68: 0.36690559 | AC68: 0.36690559 | AD68: 0.36690559 | AE68: 0.015261853 | AF68: 0.006092329 | AG68: 0.0020164185 | AH68: 0.0020164185 | AI68: 0.0014050291 | AJ68: 0.0014050291 | AK68: 0.0014050291 | AL68: 0.0014050291 | AM68: 0.0014050291 | AN68: 0.0025625017 | AO68: 0.041715145 | AP68: 0.046125031 | AQ68: 0.16836859 | AR68: 0.16836859 | AS68: 0.16836859 | AT68: 5.0313803e-07 | AU68: 0.28081034 | AV68: 0.30972217 | AW68: 0.020603835 | AX68: 0.00097503589 | AY68: 0.0010754242 | AZ68: 7.1541095e-05 | BA68: 0.13868818 | BB68: 0.35790856 | BC68: 0.00048155619 | BD68: 0.0012427381 | BE68: 0.00097503589 | BF68: 0 | BG68: 0.034269312 | BH68: 5.7918077 | BI68: 0.049611149 | BJ68: 0.0006465908 | BK68: 0 | BL68: EC

Sheet fleet_age_2019
A1: Year | B1: =metadata!B2 -> PC_MINI_G | C1: =metadata!B3 -> PC_SMALL_G | D1: =metadata!B4 -> PC_MEDIUM_G | E1: =metadata!B5 -> PC_SUV_G | F1: =metadata!B6 -> PC_MINI_D | G1: =metadata!B7 -> PC_SMALL_D | H1: =metadata!B8 -> PC_MEDIUM_D | I1: =metadata!B9 -> PC_SUV_D | J1: =metadata!B10 -> PC_ELEC | K1: =metadata!B11 -> PC_SMALL_HY | L1: =metadata!B12 -> TAXI_SMALL_G | M1: =metadata!B13 -> TAXI_SMALL_GLP | N1: =metadata!B14 -> LCV_NI_G | O1: =metadata!B15 -> LCV_NII_G | P1: =metadata!B16 -> LCV_NIII_G | Q1: =metadata!B17 -> LCV_NI_D | R1: =metadata!B18 -> LCV_NII_D | S1: =metadata!B19 -> LCV_NIII_D | T1: =metadata!B20 -> LCV_ELEC | U1: =metadata!B21 -> LCV_HY | V1: =metadata!B22 -> TRUCKS_RT_7_D | W1: =metadata!B23 -> TRUCKS_RT_7_12_D | X1: =metadata!B24 -> TRUCKS_RT_12_14_D | Y1: =metadata!B25 -> TRUCKS_RT_14_16_D | Z1: =metadata!B26 -> TRUCKS_RT_16_20_D | AA1: =metadata!B27 -> TRUCKS_RT_20_26_D | AB1: =metadata!B28 -> TRUCKS_RT_26_28_D | AC1: =metadata!B29 -> TRUCKS_RT_28_32_D | AD1: =metadata!B30 -> TRUCKS_RT_32_D | AE1: =metadata!B31 -> TRUCKS_RT_7_G | AF1: =metadata!B32 -> TRUCKS_RT_7_12_G | AG1: =metadata!B33 -> TRUCKS_RT_12_14_G | AH1: =metadata!B34 -> TRUCKS_RT_14_16_G | AI1: =metadata!B35 -> TRUCKS_RT_16_20_G | AJ1: =metadata!B36 -> TRUCKS_RT_20_26_G | AK1: =metadata!B37 -> TRUCKS_RT_26_28_G | AL1: =metadata!B38 -> TRUCKS_RT_28_32_G | AM1: =metadata!B39 -> TRUCKS_RT_32_G | AN1: =metadata!B40 -> TRUCKS_AT_16_20_D | AO1: =metadata!B41 -> TRUCKS_AT_20_28_D | AP1: =metadata!B42 -> TRUCKS_AT_28_34_D | AQ1: =metadata!B43 -> TRUCKS_AT_34_40_D | AR1: =metadata!B44 -> TRUCKS_AT_40_50_D | AS1: =metadata!B45 -> TRUCKS_AT_50_60_D | AT1: =metadata!B46 -> TRUCKS_ELEC | AU1: =metadata!B47 -> BUS_UB_15_D | AV1: =metadata!B48 -> BUS_UB_15_18_D | AW1: =metadata!B49 -> BUS_UB_18_D | AX1: =metadata!B50 -> BUS_UB_15_G | AY1: =metadata!B51 -> BUS_UB_15_18_G | AZ1: =metadata!B52 -> BUS_UB_18_G | BA1: =metadata!B53 -> BUS_COACH_17_D | BB1: =metadata!B54 -> BUS_COACH_18_D | BC1: =metadata!B55 -> BUS_COACH_17_G | BD1: =metadata!B56 -> BUS_COACH_18_G | BE1: =metadata!B57 -> BUS_UB_15_HY | BF1: =metadata!B58 -> BUS_ELEC | BG1: =metadata!B59 -> MC_2S_50_G | BH1: =metadata!B60 -> MC_4S_50_250_G | BI1: =metadata!B61 -> MC_4S_250_750_G | BJ1: =metadata!B62 -> MC_4S_750_G | BK1: =metadata!B63 -> MC_ELEC
A2: 2019 | B2: =base_fleet!H2 -> 18575 | C2: =base_fleet!M2*0.95 -> 37789.1 | D2: =base_fleet!D2 -> 1572 | E2: =base_fleet!R2 -> 14447 | F2: =base_fleet!F2 -> 116 | G2: =base_fleet!K2 -> 505 | H2: =base_fleet!B2 -> 1 | I2: =base_fleet!P2 -> 319 | J2: =base_fleet!C2+base_fleet!G2+base_fleet!L2+base_fleet!Q2 -> 4 | K2: =base_fleet!E2+base_fleet!J2+base_fleet!O2+base_fleet!T2 -> 1618 | L2: =base_fleet!M2*0.05 -> 1988.9 | M2: =base_fleet!I2+base_fleet!N2+base_fleet!S2 -> 1 | N2: =base_fleet!AF2 -> 2027 | O2: =base_fleet!AA2 -> 85 | P2: =base_fleet!V2 -> 221 | Q2: =base_fleet!AD2 -> 2749 | R2: =base_fleet!Y2 -> 148 | S2: =base_fleet!U2 -> 299 | T2: 0 | U2: =base_fleet!X2+base_fleet!AC2+base_fleet!AH2 -> 0 | V2: =base_fleet!AI2 -> 2524 | W2: =base_fleet!AM2 -> 297 | X2: =base_fleet!AP2 -> 80 | Y2: =base_fleet!AS2 -> 24 | Z2: =base_fleet!AU2 -> 99 | AA2: =base_fleet!AW2 -> 4 | AB2: =base_fleet!AY2/2 -> 8.5 | AC2: =base_fleet!AY2/2 -> 8.5 | AD2: =base_fleet!BB2 -> 18 | AE2: =base_fleet!AK2 -> 0 | AF2: =base_fleet!AO2 -> 0 | AG2: =base_fleet!AR2 -> 0 | AH2: =base_fleet!AT2 -> 0 | AI2: =base_fleet!AV2 -> 0 | AJ2: =base_fleet!AX2 -> 0 | AK2: =base_fleet!AZ2 -> 0 | AL2: =base_fleet!BC2 -> 0 | AM2: 0 | AN2: =base_fleet!BD2 -> 174 | AO2: =base_fleet!BE2 -> 109 | AP2: =base_fleet!BF2 -> 1 | AQ2: =base_fleet!BG2 -> 20 | AR2: =base_fleet!BH2 -> 98 | AS2: =base_fleet!BI2 -> 5 | AT2: =base_fleet!AQ2+base_fleet!AN2+base_fleet!AJ2 -> 0 | AU2: =base_fleet!BL2 -> 417.35 | AV2: =base_fleet!BJ2 -> 30.6 | AW2: =base_fleet!BN2 -> 17 | AX2: =base_fleet!BM2 -> 0 | AY2: =base_fleet!BK2 -> 0.85 | AZ2: =base_fleet!BO2 -> 0 | BA2: =base_fleet!BP2 -> 184.35 | BB2: =base_fleet!BR2 -> 5.25 | BC2: =base_fleet!BQ2 -> 1.95 | BD2: =base_fleet!BS2 -> 0.15 | BE2: 0 | BF2: 0 | BG2: =base_fleet!CE2 -> 0 | BH2: =base_fleet!CA2 -> 31369 | BI2: =base_fleet!BV2 -> 66 | BJ2: =base_fleet!CH2 -> 0 | BK2: =base_fleet!BU2+base_fleet!BZ2+base_fleet!CD2 -> 0
A3: =A2-1 -> 2018 | B3: =base_fleet!H3 -> 8602 | C3: =base_fleet!M3*0.95 -> 24402.65 | D3: =base_fleet!D3 -> 891 | E3: =base_fleet!R3 -> 39723 | F3: =base_fleet!F3 -> 25 | G3: =base_fleet!K3 -> 281 | H3: =base_fleet!B3 -> 15 | I3: =base_fleet!P3 -> 648 | J3: =base_fleet!C3+base_fleet!G3+base_fleet!L3+base_fleet!Q3 -> 6 | K3: =base_fleet!E3+base_fleet!J3+base_fleet!O3+base_fleet!T3 -> 1557 | L3: =base_fleet!M3*0.05 -> 1284.35 | M3: =base_fleet!I3+base_fleet!N3+base_fleet!S3 -> 1 | N3: =base_fleet!AF3 -> 9033 | O3: =base_fleet!AA3 -> 605 | P3: =base_fleet!V3 -> 946 | Q3: =base_fleet!AD3 -> 12345 | R3: =base_fleet!Y3 -> 728 | S3: =base_fleet!U3 -> 974 | T3: =base_fleet!Z3+base_fleet!AE3 -> 7 | U3: =base_fleet!X3+base_fleet!AC3+base_fleet!AH3 -> 0 | V3: =base_fleet!AI3 -> 3968 | W3: =base_fleet!AM3 -> 455 | X3: =base_fleet!AP3 -> 246 | Y3: =base_fleet!AS3 -> 111 | Z3: =base_fleet!AU3 -> 256 | AA3: =base_fleet!AW3 -> 19 | AB3: =base_fleet!AY3/2 -> 34 | AC3: =base_fleet!AY3/2 -> 34 | AD3: =base_fleet!BB3 -> 29 | AE3: =base_fleet!AK3 -> 90 | AF3: =base_fleet!AO3 -> 1 | AG3: =base_fleet!AR3 -> 0 | AH3: =base_fleet!AT3 -> 0 | AI3: =base_fleet!AV3 -> 0 | AJ3: =base_fleet!AX3 -> 0 | AK3: =base_fleet!AZ3 -> 0 | AL3: =base_fleet!BC3 -> 0 | AM3: 0 | AN3: =base_fleet!BD3 -> 304 | AO3: =base_fleet!BE3 -> 236 | AP3: =base_fleet!BF3 -> 4 | AQ3: =base_fleet!BG3 -> 14 | AR3: =base_fleet!BH3 -> 261 | AS3: =base_fleet!BI3 -> 22 | AT3: =base_fleet!AQ3+base_fleet!AN3+base_fleet!AJ3 -> 0 | AU3: =base_fleet!BL3 -> 1114.35 | AV3: =base_fleet!BJ3 -> 232.9 | AW3: =base_fleet!BN3 -> 123.25 | AX3: =base_fleet!BM3 -> 1.7 | AY3: =base_fleet!BK3 -> 1.7 | AZ3: =base_fleet!BO3 -> 0.85 | BA3: =base_fleet!BP3 -> 217.65 | BB3: =base_fleet!BR3 -> 4.5 | BC3: =base_fleet!BQ3 -> 1.8 | BD3: =base_fleet!BS3 -> 0 | BE3: 0 | BF3: 0 | BG3: =base_fleet!CE3 -> 19 | BH3: =base_fleet!CA3 -> 102301 | BI3: =base_fleet!BV3 -> 767 | BJ3: =base_fleet!CH3 -> 4 | BK3: =base_fleet!BU3+base_fleet!BZ3+base_fleet!CD3 -> 69
A4: =A3-1 -> 2017 | B4: =base_fleet!H4 -> 5522 | C4: =base_fleet!M4*0.95 -> 15650.3 | D4: =base_fleet!D4 -> 106 | E4: =base_fleet!R4 -> 24392 | F4: =base_fleet!F4 -> 1 | G4: =base_fleet!K4 -> 10 | H4: =base_fleet!B4 -> 0 | I4: =base_fleet!P4 -> 525 | J4: =base_fleet!C4+base_fleet!G4+base_fleet!L4+base_fleet!Q4 -> 87 | K4: =base_fleet!E4+base_fleet!J4+base_fleet!O4+base_fleet!T4 -> 1571 | L4: =base_fleet!M4*0.05 -> 823.7 | M4: =base_fleet!I4+base_fleet!N4+base_fleet!S4 -> 0 | N4: =base_fleet!AF4 -> 4790 | O4: =base_fleet!AA4 -> 488 | P4: =base_fleet!V4 -> 435 | Q4: =base_fleet!AD4 -> 8926 | R4: =base_fleet!Y4 -> 552 | S4: =base_fleet!U4 -> 493 | T4: =base_fleet!Z4+base_fleet!AE4 -> 0 | U4: =base_fleet!X4+base_fleet!AC4+base_fleet!AH4 -> 2 | V4: =base_fleet!AI4 -> 2936 | W4: =base_fleet!AM4 -> 342 | X4: =base_fleet!AP4 -> 222 | Y4: =base_fleet!AS4 -> 73 | Z4: =base_fleet!AU4 -> 203 | AA4: =base_fleet!AW4 -> 15 | AB4: =base_fleet!AY4/2 -> 16 | AC4: =base_fleet!AY4/2 -> 16 | AD4: =base_fleet!BB4 -> 4 | AE4: =base_fleet!AK4 -> 9 | AF4: =base_fleet!AO4 -> 0 | AG4: =base_fleet!AR4 -> 0 | AH4: =base_fleet!AT4 -> 0 | AI4: =base_fleet!AV4 -> 0 | AJ4: =base_fleet!AX4 -> 0 | AK4: =base_fleet!AZ4 -> 0 | AL4: =base_fleet!BC4 -> 0 | AM4: 0 | AN4: =base_fleet!BD4 -> 164 | AO4: =base_fleet!BE4 -> 90 | AP4: =base_fleet!BF4 -> 1 | AQ4: =base_fleet!BG4 -> 22 | AR4: =base_fleet!BH4 -> 71 | AS4: =base_fleet!BI4 -> 7 | AT4: =base_fleet!AQ4+base_fleet!AN4+base_fleet!AJ4 -> 0 | AU4: =base_fleet!BL4 -> 1210.4 | AV4: =base_fleet!BJ4 -> 302.6 | AW4: =base_fleet!BN4 -> 66.3 | AX4: =base_fleet!BM4 -> 3.4 | AY4: =base_fleet!BK4 -> 0 | AZ4: =base_fleet!BO4 -> 0 | BA4: =base_fleet!BP4 -> 224.1 | BB4: =base_fleet!BR4 -> 0.15 | BC4: =base_fleet!BQ4 -> 1.8 | BD4: =base_fleet!BS4 -> 0 | BE4: 0 | BF4: 0 | BG4: =base_fleet!CE4 -> 3 | BH4: =base_fleet!CA4 -> 73869 | BI4: =base_fleet!BV4 -> 1485 | BJ4: =base_fleet!CH4 -> 2 | BK4: =base_fleet!BU4+base_fleet!BZ4+base_fleet!CD4 -> 76
A5: =A4-1 -> 2016 | B5: =base_fleet!H5 -> 4030 | C5: =base_fleet!M5*0.95 -> 13349.4 | D5: =base_fleet!D5 -> 201 | E5: =base_fleet!R5 -> 14707 | F5: =base_fleet!F5 -> 1 | G5: =base_fleet!K5 -> 193 | H5: =base_fleet!B5 -> 1 | I5: =base_fleet!P5 -> 460 | J5: =base_fleet!C5+base_fleet!G5+base_fleet!L5+base_fleet!Q5 -> 43 | K5: =base_fleet!E5+base_fleet!J5+base_fleet!O5+base_fleet!T5 -> 553 | L5: =base_fleet!M5*0.05 -> 702.6 | M5: =base_fleet!I5+base_fleet!N5+base_fleet!S5 -> 1 | N5: =base_fleet!AF5 -> 2649 | O5: =base_fleet!AA5 -> 390 | P5: =base_fleet!V5 -> 365 | Q5: =base_fleet!AD5 -> 5916 | R5: =base_fleet!Y5 -> 353 | S5: =base_fleet!U5 -> 801 | T5: =base_fleet!Z5+base_fleet!AE5 -> 0 | U5: =base_fleet!X5+base_fleet!AC5+base_fleet!AH5 -> 0 | V5: =base_fleet!AI5 -> 1045 | W5: =base_fleet!AM5 -> 159 | X5: =base_fleet!AP5 -> 18 | Y5: =base_fleet!AS5 -> 45 | Z5: =base_fleet!AU5 -> 43 | AA5: =base_fleet!AW5 -> 10 | AB5: =base_fleet!AY5/2 -> 4 | AC5: =base_fleet!AY5/2 -> 4 | AD5: =base_fleet!BB5 -> 1 | AE5: =base_fleet!AK5 -> 13 | AF5: =base_fleet!AO5 -> 1 | AG5: =base_fleet!AR5 -> 0 | AH5: =base_fleet!AT5 -> 0 | AI5: =base_fleet!AV5 -> 0 | AJ5: =base_fleet!AX5 -> 0 | AK5: =base_fleet!AZ5 -> 0 | AL5: =base_fleet!BC5 -> 0 | AM5: 0 | AN5: =base_fleet!BD5 -> 21 | AO5: =base_fleet!BE5 -> 1 | AP5: =base_fleet!BF5 -> 0 | AQ5: =base_fleet!BG5 -> 0 | AR5: =base_fleet!BH5 -> 1 | AS5: =base_fleet!BI5 -> 0 | AT5: =base_fleet!AQ5+base_fleet!AN5+base_fleet!AJ5 -> 0 | AU5: =base_fleet!BL5 -> 939.25 | AV5: =base_fleet!BJ5 -> 75.65 | AW5: =base_fleet!BN5 -> 17 | AX5: =base_fleet!BM5 -> 1.7 | AY5: =base_fleet!BK5 -> 0 | AZ5: =base_fleet!BO5 -> 0 | BA5: =base_fleet!BP5 -> 162.15 | BB5: =base_fleet!BR5 -> 1.35 | BC5: =base_fleet!BQ5 -> 1.35 | BD5: =base_fleet!BS5 -> 0 | BE5: 0 | BF5: 0 | BG5: =base_fleet!CE5 -> 0 | BH5: =base_fleet!CA5 -> 37270 | BI5: =base_fleet!BV5 -> 465 | BJ5: =base_fleet!CH5 -> 0 | BK5: =base_fleet!BU5+base_fleet!BZ5+base_fleet!CD5 -> 6
A6: =A5-1 -> 2015 | B6: =base_fleet!H6 -> 9792 | C6: =base_fleet!M6*0.95 -> 23799.4 | D6: =base_fleet!D6 -> 36 | E6: =base_fleet!R6 -> 12476 | F6: =base_fleet!F6 -> 1 | G6: =base_fleet!K6 -> 15 | H6: =base_fleet!B6 -> 2 | I6: =base_fleet!P6 -> 123 | J6: =base_fleet!C6+base_fleet!G6+base_fleet!L6+base_fleet!Q6 -> 68 | K6: =base_fleet!E6+base_fleet!J6+base_fleet!O6+base_fleet!T6 -> 717 | L6: =base_fleet!M6*0.05 -> 1252.6 | M6: =base_fleet!I6+base_fleet!N6+base_fleet!S6 -> 1 | N6: =base_fleet!AF6 -> 3757 | O6: =base_fleet!AA6 -> 293 | P6: =base_fleet!V6 -> 1085 | Q6: =base_fleet!AD6 -> 4351 | R6: =base_fleet!Y6 -> 192 | S6: =base_fleet!U6 -> 961 | T6: =base_fleet!Z6+base_fleet!AE6 -> 3 | U6: =base_fleet!X6+base_fleet!AC6+base_fleet!AH6 -> 1 | V6: =base_fleet!AI6 -> 3185 | W6: =base_fleet!AM6 -> 328 | X6: =base_fleet!AP6 -> 81 | Y6: =base_fleet!AS6 -> 200 | Z6: =base_fleet!AU6 -> 165 | AA6: =base_fleet!AW6 -> 18 | AB6: =base_fleet!AY6/2 -> 9.5 | AC6: =base_fleet!AY6/2 -> 9.5 | AD6: =base_fleet!BB6 -> 2 | AE6: =base_fleet!AK6 -> 45 | AF6: =base_fleet!AO6 -> 3 | AG6: =base_fleet!AR6 -> 0 | AH6: =base_fleet!AT6 -> 0 | AI6: =base_fleet!AV6 -> 2 | AJ6: =base_fleet!AX6 -> 0 | AK6: =base_fleet!AZ6 -> 1 | AL6: =base_fleet!BC6 -> 0 | AM6: 0 | AN6: =base_fleet!BD6 -> 118 | AO6: =base_fleet!BE6 -> 112 | AP6: =base_fleet!BF6 -> 3 | AQ6: =base_fleet!BG6 -> 14 | AR6: =base_fleet!BH6 -> 46 | AS6: =base_fleet!BI6 -> 11 | AT6: =base_fleet!AQ6+base_fleet!AN6+base_fleet!AJ6 -> 1 | AU6: =base_fleet!BL6 -> 1212.95 | AV6: =base_fleet!BJ6 -> 135.15 | AW6: =base_fleet!BN6 -> 61.2 | AX6: =base_fleet!BM6 -> 9.35 | AY6: =base_fleet!BK6 -> 0.85 | AZ6: =base_fleet!BO6 -> 0 | BA6: =base_fleet!BP6 -> 169.65 | BB6: =base_fleet!BR6 -> 0.3 | BC6: =base_fleet!BQ6 -> 1.35 | BD6: =base_fleet!BS6 -> 0 | BE6: 0 | BF6: 0 | BG6: =base_fleet!CE6 -> 6 | BH6: =base_fleet!CA6 -> 24810 | BI6: =base_fleet!BV6 -> 86 | BJ6: =base_fleet!CH6 -> 2 | BK6: =base_fleet!BU6+base_fleet!BZ6+base_fleet!CD6 -> 1
A7: =A6-1 -> 2014 | B7: =base_fleet!H7 -> 15449 | C7: =base_fleet!M7*0.95 -> 17061.05 | D7: =base_fleet!D7 -> 78 | E7: =base_fleet!R7 -> 24529 | F7: =base_fleet!F7 -> 1 | G7: =base_fleet!K7 -> 25 | H7: =base_fleet!B7 -> 2 | I7: =base_fleet!P7 -> 93 | J7: =base_fleet!C7+base_fleet!G7+base_fleet!L7+base_fleet!Q7 -> 2 | K7: =base_fleet!E7+base_fleet!J7+base_fleet!O7+base_fleet!T7 -> 85 | L7: =base_fleet!M7*0.05 -> 897.95 | M7: =base_fleet!I7+base_fleet!N7+base_fleet!S7 -> 3 | N7: =base_fleet!AF7 -> 7747 | O7: =base_fleet!AA7 -> 886 | P7: =base_fleet!V7 -> 1496 | Q7: =base_fleet!AD7 -> 8830 | R7: =base_fleet!Y7 -> 648 | S7: =base_fleet!U7 -> 1991 | T7: =base_fleet!Z7+base_fleet!AE7 -> 0 | U7: =base_fleet!X7+base_fleet!AC7+base_fleet!AH7 -> 1 | V7: =base_fleet!AI7 -> 6124 | W7: =base_fleet!AM7 -> 1072 | X7: =base_fleet!AP7 -> 197 | Y7: =base_fleet!AS7 -> 591 | Z7: =base_fleet!AU7 -> 495 | AA7: =base_fleet!AW7 -> 162 | AB7: =base_fleet!AY7/2 -> 103.5 | AC7: =base_fleet!AY7/2 -> 103.5 | AD7: =base_fleet!BB7 -> 8 | AE7: =base_fleet!AK7 -> 60 | AF7: =base_fleet!AO7 -> 5 | AG7: =base_fleet!AR7 -> 2 | AH7: =base_fleet!AT7 -> 2 | AI7: =base_fleet!AV7 -> 5 | AJ7: =base_fleet!AX7 -> 0 | AK7: =base_fleet!AZ7 -> 4 | AL7: =base_fleet!BC7 -> 0 | AM7: 0 | AN7: =base_fleet!BD7 -> 224 | AO7: =base_fleet!BE7 -> 661 | AP7: =base_fleet!BF7 -> 7 | AQ7: =base_fleet!BG7 -> 174 | AR7: =base_fleet!BH7 -> 307 | AS7: =base_fleet!BI7 -> 5 | AT7: =base_fleet!AQ7+base_fleet!AN7+base_fleet!AJ7 -> 0 | AU7: =base_fleet!BL7 -> 1134.75 | AV7: =base_fleet!BJ7 -> 112.2 | AW7: =base_fleet!BN7 -> 68 | AX7: =base_fleet!BM7 -> 10.2 | AY7: =base_fleet!BK7 -> 0 | AZ7: =base_fleet!BO7 -> 0 | BA7: =base_fleet!BP7 -> 198.6 | BB7: =base_fleet!BR7 -> 2.85 | BC7: =base_fleet!BQ7 -> 1.65 | BD7: =base_fleet!BS7 -> 0 | BE7: 0 | BF7: 0 | BG7: =base_fleet!CE7 -> 67 | BH7: =base_fleet!CA7 -> 53787 | BI7: =base_fleet!BV7 -> 127 | BJ7: =base_fleet!CH7 -> 4 | BK7: =base_fleet!BU7+base_fleet!BZ7+base_fleet!CD7 -> 0
A8: =A7-1 -> 2013 | B8: =base_fleet!H8 -> 20796 | C8: =base_fleet!M8*0.95 -> 19845.5 | D8: =base_fleet!D8 -> 64 | E8: =base_fleet!R8 -> 21361 | F8: =base_fleet!F8 -> 3 | G8: =base_fleet!K8 -> 30 | H8: =base_fleet!B8 -> 2 | I8: =base_fleet!P8 -> 74 | J8: =base_fleet!C8+base_fleet!G8+base_fleet!L8+base_fleet!Q8 -> 1 | K8: =base_fleet!E8+base_fleet!J8+base_fleet!O8+base_fleet!T8 -> 342 | L8: =base_fleet!M8*0.05 -> 1044.5 | M8: =base_fleet!I8+base_fleet!N8+base_fleet!S8 -> 2 | N8: =base_fleet!AF8 -> 7038 | O8: =base_fleet!AA8 -> 731 | P8: =base_fleet!V8 -> 1226 | Q8: =base_fleet!AD8 -> 7922 | R8: =base_fleet!Y8 -> 745 | S8: =base_fleet!U8 -> 1266 | T8: =base_fleet!Z8+base_fleet!AE8 -> 0 | U8: =base_fleet!X8+base_fleet!AC8+base_fleet!AH8 -> 1 | V8: =base_fleet!AI8 -> 4776 | W8: =base_fleet!AM8 -> 588 | X8: =base_fleet!AP8 -> 259 | Y8: =base_fleet!AS8 -> 128 | Z8: =base_fleet!AU8 -> 501 | AA8: =base_fleet!AW8 -> 131 | AB8: =base_fleet!AY8/2 -> 68 | AC8: =base_fleet!AY8/2 -> 68 | AD8: =base_fleet!BB8 -> 17 | AE8: =base_fleet!AK8 -> 17 | AF8: =base_fleet!AO8 -> 3 | AG8: =base_fleet!AR8 -> 0 | AH8: =base_fleet!AT8 -> 0 | AI8: =base_fleet!AV8 -> 2 | AJ8: =base_fleet!AX8 -> 2 | AK8: =base_fleet!AZ8 -> 0 | AL8: =base_fleet!BC8 -> 1 | AM8: 0 | AN8: =base_fleet!BD8 -> 217 | AO8: =base_fleet!BE8 -> 552 | AP8: =base_fleet!BF8 -> 16 | AQ8: =base_fleet!BG8 -> 174 | AR8: =base_fleet!BH8 -> 183 | AS8: =base_fleet!BI8 -> 8 | AT8: =base_fleet!AQ8+base_fleet!AN8+base_fleet!AJ8 -> 0 | AU8: =base_fleet!BL8 -> 1153.45 | AV8: =base_fleet!BJ8 -> 281.35 | AW8: =base_fleet!BN8 -> 24.65 | AX8: =base_fleet!BM8 -> 1.7 | AY8: =base_fleet!BK8 -> 0 | AZ8: =base_fleet!BO8 -> 0 | BA8: =base_fleet!BP8 -> 114.15 | BB8: =base_fleet!BR8 -> 0.45 | BC8: =base_fleet!BQ8 -> 1.05 | BD8: =base_fleet!BS8 -> 0 | BE8: 0 | BF8: 0 | BG8: =base_fleet!CE8 -> 35 | BH8: =base_fleet!CA8 -> 46591 | BI8: =base_fleet!BV8 -> 365 | BJ8: =base_fleet!CH8 -> 10 | BK8: =base_fleet!BU8+base_fleet!BZ8+base_fleet!CD8 -> 5
A9: =A8-1 -> 2012 | B9: =base_fleet!H9 -> 17643 | C9: =base_fleet!M9*0.95 -> 25065.75 | D9: =base_fleet!D9 -> 64 | E9: =base_fleet!R9 -> 23514 | F9: =base_fleet!F9 -> 6 | G9: =base_fleet!K9 -> 35 | H9: =base_fleet!B9 -> 1 | I9: =base_fleet!P9 -> 124 | J9: =base_fleet!C9+base_fleet!G9+base_fleet!L9+base_fleet!Q9 -> 1 | K9: =base_fleet!E9+base_fleet!J9+base_fleet!O9+base_fleet!T9 -> 272 | L9: =base_fleet!M9*0.05 -> 1319.25 | M9: =base_fleet!I9+base_fleet!N9+base_fleet!S9 -> 2 | N9: =base_fleet!AF9 -> 12369 | O9: =base_fleet!AA9 -> 1400 | P9: =base_fleet!V9 -> 569 | Q9: =base_fleet!AD9 -> 9792 | R9: =base_fleet!Y9 -> 908 | S9: =base_fleet!U9 -> 456 | T9: =base_fleet!Z9+base_fleet!AE9 -> 3 | U9: =base_fleet!X9+base_fleet!AC9+base_fleet!AH9 -> 0 | V9: =base_fleet!AI9 -> 5860 | W9: =base_fleet!AM9 -> 532 | X9: =base_fleet!AP9 -> 335 | Y9: =base_fleet!AS9 -> 126 | Z9: =base_fleet!AU9 -> 412 | AA9: =base_fleet!AW9 -> 343 | AB9: =base_fleet!AY9/2 -> 56 | AC9: =base_fleet!AY9/2 -> 56 | AD9: =base_fleet!BB9 -> 69 | AE9: =base_fleet!AK9 -> 50 | AF9: =base_fleet!AO9 -> 6 | AG9: =base_fleet!AR9 -> 1 | AH9: =base_fleet!AT9 -> 1 | AI9: =base_fleet!AV9 -> 1 | AJ9: =base_fleet!AX9 -> 6 | AK9: =base_fleet!AZ9 -> 0 | AL9: =base_fleet!BC9 -> 0 | AM9: 0 | AN9: =base_fleet!BD9 -> 219 | AO9: =base_fleet!BE9 -> 523 | AP9: =base_fleet!BF9 -> 15 | AQ9: =base_fleet!BG9 -> 163 | AR9: =base_fleet!BH9 -> 213 | AS9: =base_fleet!BI9 -> 0 | AT9: =base_fleet!AQ9+base_fleet!AN9+base_fleet!AJ9 -> 1 | AU9: =base_fleet!BL9 -> 848.3 | AV9: =base_fleet!BJ9 -> 272 | AW9: =base_fleet!BN9 -> 10.2 | AX9: =base_fleet!BM9 -> 2.55 | AY9: =base_fleet!BK9 -> 0 | AZ9: =base_fleet!BO9 -> 0 | BA9: =base_fleet!BP9 -> 230.7 | BB9: =base_fleet!BR9 -> 2.7 | BC9: =base_fleet!BQ9 -> 2.1 | BD9: =base_fleet!BS9 -> 0 | BE9: 0 | BF9: 0 | BG9: =base_fleet!CE9 -> 11 | BH9: =base_fleet!CA9 -> 34545 | BI9: =base_fleet!BV9 -> 398 | BJ9: =base_fleet!CH9 -> 31 | BK9: =base_fleet!BU9+base_fleet!BZ9+base_fleet!CD9 -> 4
A10: =A9-1 -> 2011 | B10: =base_fleet!H10 -> 16182 | C10: =base_fleet!M10*0.95 -> 32241.1 | D10: =base_fleet!D10 -> 172 | E10: =base_fleet!R10 -> 22476 | F10: =base_fleet!F10 -> 18 | G10: =base_fleet!K10 -> 100 | H10: =base_fleet!B10 -> 1 | I10: =base_fleet!P10 -> 81 | J10: =base_fleet!C10+base_fleet!G10+base_fleet!L10+base_fleet!Q10 -> 2 | K10: =base_fleet!E10+base_fleet!J10+base_fleet!O10+base_fleet!T10 -> 241 | L10: =base_fleet!M10*0.05 -> 1696.9 | M10: =base_fleet!I10+base_fleet!N10+base_fleet!S10 -> 7 | N10: =base_fleet!AF10 -> 11933 | O10: =base_fleet!AA10 -> 2066 | P10: =base_fleet!V10 -> 246 | Q10: =base_fleet!AD10 -> 7033 | R10: =base_fleet!Y10 -> 696 | S10: =base_fleet!U10 -> 586 | T10: =base_fleet!Z10+base_fleet!AE10 -> 0 | U10: =base_fleet!X10+base_fleet!AC10+base_fleet!AH10 -> 1 | V10: =base_fleet!AI10 -> 4794 | W10: =base_fleet!AM10 -> 688 | X10: =base_fleet!AP10 -> 607 | Y10: =base_fleet!AS10 -> 81 | Z10: =base_fleet!AU10 -> 304 | AA10: =base_fleet!AW10 -> 311 | AB10: =base_fleet!AY10/2 -> 4.5 | AC10: =base_fleet!AY10/2 -> 4.5 | AD10: =base_fleet!BB10 -> 36 | AE10: =base_fleet!AK10 -> 50 | AF10: =base_fleet!AO10 -> 4 | AG10: =base_fleet!AR10 -> 4 | AH10: =base_fleet!AT10 -> 0 | AI10: =base_fleet!AV10 -> 1 | AJ10: =base_fleet!AX10 -> 4 | AK10: =base_fleet!AZ10 -> 0 | AL10: =base_fleet!BC10 -> 0 | AM10: 0 | AN10: =base_fleet!BD10 -> 243 | AO10: =base_fleet!BE10 -> 338 | AP10: =base_fleet!BF10 -> 28 | AQ10: =base_fleet!BG10 -> 159 | AR10: =base_fleet!BH10 -> 180 | AS10: =base_fleet!BI10 -> 2 | AT10: =base_fleet!AQ10+base_fleet!AN10+base_fleet!AJ10 -> 0 | AU10: =base_fleet!BL10 -> 935 | AV10: =base_fleet!BJ10 -> 165.75 | AW10: =base_fleet!BN10 -> 4.25 | AX10: =base_fleet!BM10 -> 4.25 | AY10: =base_fleet!BK10 -> 2.55 | AZ10: =base_fleet!BO10 -> 0 | BA10: =base_fleet!BP10 -> 194.25 | BB10: =base_fleet!BR10 -> 0.75 | BC10: =base_fleet!BQ10 -> 1.2 | BD10: =base_fleet!BS10 -> 0 | BE10: 0 | BF10: 0 | BG10: =base_fleet!CE10 -> 4 | BH10: =base_fleet!CA10 -> 36287 | BI10: =base_fleet!BV10 -> 318 | BJ10: =base_fleet!CH10 -> 1 | BK10: =base_fleet!BU10+base_fleet!BZ10+base_fleet!CD10 -> 1
A11: =A10-1 -> 2010 | B11: =base_fleet!H11 -> 11486 | C11: =base_fleet!M11*0.95 -> 16687.7 | D11: =base_fleet!D11 -> 11 | E11: =base_fleet!R11 -> 25762 | F11: =base_fleet!F11 -> 15 | G11: =base_fleet!K11 -> 116 | H11: =base_fleet!B11 -> 3 | I11: =base_fleet!P11 -> 135 | J11: =base_fleet!C11+base_fleet!G11+base_fleet!L11+base_fleet!Q11 -> 2 | K11: =base_fleet!E11+base_fleet!J11+base_fleet!O11+base_fleet!T11 -> 1154 | L11: =base_fleet!M11*0.05 -> 878.3 | M11: =base_fleet!I11+base_fleet!N11+base_fleet!S11 -> 4 | N11: =base_fleet!AF11 -> 13738 | O11: =base_fleet!AA11 -> 1114 | P11: =base_fleet!V11 -> 184 | Q11: =base_fleet!AD11 -> 9413 | R11: =base_fleet!Y11 -> 914 | S11: =base_fleet!U11 -> 758 | T11: =base_fleet!Z11+base_fleet!AE11 -> 0 | U11: =base_fleet!X11+base_fleet!AC11+base_fleet!AH11 -> 73 | V11: =base_fleet!AI11 -> 4665 | W11: =base_fleet!AM11 -> 962 | X11: =base_fleet!AP11 -> 450 | Y11: =base_fleet!AS11 -> 125 | Z11: =base_fleet!AU11 -> 243 | AA11: =base_fleet!AW11 -> 80 | AB11: =base_fleet!AY11/2 -> 17 | AC11: =base_fleet!AY11/2 -> 17 | AD11: =base_fleet!BB11 -> 12 | AE11: =base_fleet!AK11 -> 72 | AF11: =base_fleet!AO11 -> 5 | AG11: =base_fleet!AR11 -> 2 | AH11: =base_fleet!AT11 -> 3 | AI11: =base_fleet!AV11 -> 1 | AJ11: =base_fleet!AX11 -> 1 | AK11: =base_fleet!AZ11 -> 0 | AL11: =base_fleet!BC11 -> 0 | AM11: 0 | AN11: =base_fleet!BD11 -> 217 | AO11: =base_fleet!BE11 -> 343 | AP11: =base_fleet!BF11 -> 34 | AQ11: =base_fleet!BG11 -> 96 | AR11: =base_fleet!BH11 -> 75 | AS11: =base_fleet!BI11 -> 0 | AT11: =base_fleet!AQ11+base_fleet!AN11+base_fleet!AJ11 -> 0 | AU11: =base_fleet!BL11 -> 1021.7 | AV11: =base_fleet!BJ11 -> 285.6 | AW11: =base_fleet!BN11 -> 15.3 | AX11: =base_fleet!BM11 -> 10.2 | AY11: =base_fleet!BK11 -> 1.7 | AZ11: =base_fleet!BO11 -> 0 | BA11: =base_fleet!BP11 -> 197.7 | BB11: =base_fleet!BR11 -> 1.8 | BC11: =base_fleet!BQ11 -> 0.45 | BD11: =base_fleet!BS11 -> 0 | BE11: 0 | BF11: 0 | BG11: =base_fleet!CE11 -> 5 | BH11: =base_fleet!CA11 -> 22764 | BI11: =base_fleet!BV11 -> 50 | BJ11: =base_fleet!CH11 -> 3 | BK11: =base_fleet!BU11+base_fleet!BZ11+base_fleet!CD11 -> 1
A12: =A11-1 -> 2009 | B12: =base_fleet!H12 -> 16179 | C12: =base_fleet!M12*0.95 -> 16883.4 | D12: =base_fleet!D12 -> 9 | E12: =base_fleet!R12 -> 18996 | F12: =base_fleet!F12 -> 46 | G12: =base_fleet!K12 -> 125 | H12: =base_fleet!B12 -> 2 | I12: =base_fleet!P12 -> 604 | J12: =base_fleet!C12+base_fleet!G12+base_fleet!L12+base_fleet!Q12 -> 4 | K12: =base_fleet!E12+base_fleet!J12+base_fleet!O12+base_fleet!T12 -> 1619 | L12: =base_fleet!M12*0.05 -> 888.6 | M12: =base_fleet!I12+base_fleet!N12+base_fleet!S12 -> 8 | N12: =base_fleet!AF12 -> 11742 | O12: =base_fleet!AA12 -> 710 | P12: =base_fleet!V12 -> 144 | Q12: =base_fleet!AD12 -> 5850 | R12: =base_fleet!Y12 -> 539 | S12: =base_fleet!U12 -> 344 | T12: =base_fleet!Z12+base_fleet!AE12 -> 0 | U12: =base_fleet!X12+base_fleet!AC12+base_fleet!AH12 -> 32 | V12: =base_fleet!AI12 -> 2385 | W12: =base_fleet!AM12 -> 567 | X12: =base_fleet!AP12 -> 404 | Y12: =base_fleet!AS12 -> 226 | Z12: =base_fleet!AU12 -> 256 | AA12: =base_fleet!AW12 -> 119 | AB12: =base_fleet!AY12/2 -> 4.5 | AC12: =base_fleet!AY12/2 -> 4.5 | AD12: =base_fleet!BB12 -> 15 | AE12: =base_fleet!AK12 -> 39 | AF12: =base_fleet!AO12 -> 5 | AG12: =base_fleet!AR12 -> 1 | AH12: =base_fleet!AT12 -> 3 | AI12: =base_fleet!AV12 -> 0 | AJ12: =base_fleet!AX12 -> 1 | AK12: =base_fleet!AZ12 -> 0 | AL12: =base_fleet!BC12 -> 0 | AM12: 0 | AN12: =base_fleet!BD12 -> 176 | AO12: =base_fleet!BE12 -> 206 | AP12: =base_fleet!BF12 -> 31 | AQ12: =base_fleet!BG12 -> 92 | AR12: =base_fleet!BH12 -> 58 | AS12: =base_fleet!BI12 -> 0 | AT12: =base_fleet!AQ12+base_fleet!AN12+base_fleet!AJ12 -> 0 | AU12: =base_fleet!BL12 -> 609.45 | AV12: =base_fleet!BJ12 -> 37.4 | AW12: =base_fleet!BN12 -> 2.55 | AX12: =base_fleet!BM12 -> 5.95 | AY12: =base_fleet!BK12 -> 0 | AZ12: =base_fleet!BO12 -> 0 | BA12: =base_fleet!BP12 -> 253.2 | BB12: =base_fleet!BR12 -> 4.35 | BC12: =base_fleet!BQ12 -> 0.3 | BD12: =base_fleet!BS12 -> 0 | BE12: 0 | BF12: 0 | BG12: =base_fleet!CE12 -> 1 | BH12: =base_fleet!CA12 -> 18274 | BI12: =base_fleet!BV12 -> 65 | BJ12: =base_fleet!CH12 -> 0 | BK12: =base_fleet!BU12+base_fleet!BZ12+base_fleet!CD12 -> 0
